****EPOCH 0****
Numerical error at step 1
Error details: Input to reshape is a tensor with 524288 values, but the requested shape requires a multiple of 6
	 [[{{node inference/fc0/Reshape}} = Reshape[T=DT_FLOAT, Tshape=DT_INT32, _device="/job:localhost/replica:0/task:0/device:CPU:0"](inference/Cast, inference/fc0/Reshape/shape)]]

Caused by op 'inference/fc0/Reshape', defined at:
  File "main_Semantic3D.py", line 719, in <module>
    model = Network(dataset, cfg)
  File "D:\RandLA-Net\RandLANet.py", line 1222, in __init__
    self.logits = self.inference(self.inputs, self.is_training)
  File "D:\RandLA-Net\RandLANet.py", line 1263, in inference
    f0_flat = tf.reshape(feat0, [-1, C0])  # [B*N, C0]
  File "C:\Users\Ayaan\anaconda3\envs\randlanet\lib\site-packages\tensorflow\python\ops\gen_array_ops.py", line 7546, in reshape
    "Reshape", tensor=tensor, shape=shape, name=name)
  File "C:\Users\Ayaan\anaconda3\envs\randlanet\lib\site-packages\tensorflow\python\framework\op_def_library.py", line 787, in _apply_op_helper
    op_def=op_def)
  File "C:\Users\Ayaan\anaconda3\envs\randlanet\lib\site-packages\tensorflow\python\util\deprecation.py", line 488, in new_func
    return func(*args, **kwargs)
  File "C:\Users\Ayaan\anaconda3\envs\randlanet\lib\site-packages\tensorflow\python\framework\ops.py", line 3272, in create_op
    op_def=op_def)
  File "C:\Users\Ayaan\anaconda3\envs\randlanet\lib\site-packages\tensorflow\python\framework\ops.py", line 1768, in __init__
    self._traceback = tf_stack.extract_stack()

InvalidArgumentError (see above for traceback): Input to reshape is a tensor with 524288 values, but the requested shape requires a multiple of 6
	 [[{{node inference/fc0/Reshape}} = Reshape[T=DT_FLOAT, Tshape=DT_INT32, _device="/job:localhost/replica:0/task:0/device:CPU:0"](inference/Cast, inference/fc0/Reshape/shape)]]

****EPOCH 0****
Numerical error at step 1
Error details: Input to reshape is a tensor with 524288 values, but the requested shape requires a multiple of 6
	 [[{{node inference/fc0/Reshape}} = Reshape[T=DT_FLOAT, Tshape=DT_INT32, _device="/job:localhost/replica:0/task:0/device:CPU:0"](inference/Cast, inference/fc0/Reshape/shape)]]

Caused by op 'inference/fc0/Reshape', defined at:
  File "main_Semantic3D.py", line 719, in <module>
    model = Network(dataset, cfg)
  File "D:\RandLA-Net\RandLANet.py", line 1222, in __init__
    self.logits = self.inference(self.inputs, self.is_training)
  File "D:\RandLA-Net\RandLANet.py", line 1263, in inference
    f0_flat = tf.reshape(feat0, [-1, C0])  # [B*N, C0]
  File "C:\Users\Ayaan\anaconda3\envs\randlanet\lib\site-packages\tensorflow\python\ops\gen_array_ops.py", line 7546, in reshape
    "Reshape", tensor=tensor, shape=shape, name=name)
  File "C:\Users\Ayaan\anaconda3\envs\randlanet\lib\site-packages\tensorflow\python\framework\op_def_library.py", line 787, in _apply_op_helper
    op_def=op_def)
  File "C:\Users\Ayaan\anaconda3\envs\randlanet\lib\site-packages\tensorflow\python\util\deprecation.py", line 488, in new_func
    return func(*args, **kwargs)
  File "C:\Users\Ayaan\anaconda3\envs\randlanet\lib\site-packages\tensorflow\python\framework\ops.py", line 3272, in create_op
    op_def=op_def)
  File "C:\Users\Ayaan\anaconda3\envs\randlanet\lib\site-packages\tensorflow\python\framework\ops.py", line 1768, in __init__
    self._traceback = tf_stack.extract_stack()

InvalidArgumentError (see above for traceback): Input to reshape is a tensor with 524288 values, but the requested shape requires a multiple of 6
	 [[{{node inference/fc0/Reshape}} = Reshape[T=DT_FLOAT, Tshape=DT_INT32, _device="/job:localhost/replica:0/task:0/device:CPU:0"](inference/Cast, inference/fc0/Reshape/shape)]]

****EPOCH 0****
Numerical error at step 1
Error details: Input to reshape is a tensor with 524288 values, but the requested shape requires a multiple of 6
	 [[{{node inference/fc0/Reshape}} = Reshape[T=DT_FLOAT, Tshape=DT_INT32, _device="/job:localhost/replica:0/task:0/device:CPU:0"](inference/Cast, inference/fc0/Reshape/shape)]]

Caused by op 'inference/fc0/Reshape', defined at:
  File "main_Semantic3D.py", line 719, in <module>
    model = Network(dataset, cfg)
  File "D:\RandLA-Net\RandLANet.py", line 1222, in __init__
    self.logits = self.inference(self.inputs, self.is_training)
  File "D:\RandLA-Net\RandLANet.py", line 1263, in inference
    f0_flat = tf.reshape(feat0, [-1, C0])  # [B*N, C0]
  File "C:\Users\Ayaan\anaconda3\envs\randlanet\lib\site-packages\tensorflow\python\ops\gen_array_ops.py", line 7546, in reshape
    "Reshape", tensor=tensor, shape=shape, name=name)
  File "C:\Users\Ayaan\anaconda3\envs\randlanet\lib\site-packages\tensorflow\python\framework\op_def_library.py", line 787, in _apply_op_helper
    op_def=op_def)
  File "C:\Users\Ayaan\anaconda3\envs\randlanet\lib\site-packages\tensorflow\python\util\deprecation.py", line 488, in new_func
    return func(*args, **kwargs)
  File "C:\Users\Ayaan\anaconda3\envs\randlanet\lib\site-packages\tensorflow\python\framework\ops.py", line 3272, in create_op
    op_def=op_def)
  File "C:\Users\Ayaan\anaconda3\envs\randlanet\lib\site-packages\tensorflow\python\framework\ops.py", line 1768, in __init__
    self._traceback = tf_stack.extract_stack()

InvalidArgumentError (see above for traceback): Input to reshape is a tensor with 524288 values, but the requested shape requires a multiple of 6
	 [[{{node inference/fc0/Reshape}} = Reshape[T=DT_FLOAT, Tshape=DT_INT32, _device="/job:localhost/replica:0/task:0/device:CPU:0"](inference/Cast, inference/fc0/Reshape/shape)]]

****EPOCH 0****
****EPOCH 0****
Numerical error at step 1
Error details: Input to reshape is a tensor with 524288 values, but the requested shape requires a multiple of 6
	 [[{{node inference/fc0/Reshape}} = Reshape[T=DT_FLOAT, Tshape=DT_INT32, _device="/job:localhost/replica:0/task:0/device:CPU:0"](inference/Cast, inference/fc0/Reshape/shape)]]

Caused by op 'inference/fc0/Reshape', defined at:
  File "main_Semantic3D.py", line 710, in <module>
    model = Network(dataset, cfg)
  File "D:\RandLA-Net\RandLANet.py", line 1233, in __init__
    self.logits = self.inference(self.inputs, self.is_training)
  File "D:\RandLA-Net\RandLANet.py", line 1271, in inference
    f0_flat = tf.reshape(feat0, [-1, C0])  # [B*N, C0]
  File "C:\Users\Ayaan\anaconda3\envs\randlanet\lib\site-packages\tensorflow\python\ops\gen_array_ops.py", line 7546, in reshape
    "Reshape", tensor=tensor, shape=shape, name=name)
  File "C:\Users\Ayaan\anaconda3\envs\randlanet\lib\site-packages\tensorflow\python\framework\op_def_library.py", line 787, in _apply_op_helper
    op_def=op_def)
  File "C:\Users\Ayaan\anaconda3\envs\randlanet\lib\site-packages\tensorflow\python\util\deprecation.py", line 488, in new_func
    return func(*args, **kwargs)
  File "C:\Users\Ayaan\anaconda3\envs\randlanet\lib\site-packages\tensorflow\python\framework\ops.py", line 3272, in create_op
    op_def=op_def)
  File "C:\Users\Ayaan\anaconda3\envs\randlanet\lib\site-packages\tensorflow\python\framework\ops.py", line 1768, in __init__
    self._traceback = tf_stack.extract_stack()

InvalidArgumentError (see above for traceback): Input to reshape is a tensor with 524288 values, but the requested shape requires a multiple of 6
	 [[{{node inference/fc0/Reshape}} = Reshape[T=DT_FLOAT, Tshape=DT_INT32, _device="/job:localhost/replica:0/task:0/device:CPU:0"](inference/Cast, inference/fc0/Reshape/shape)]]

Saved crash snapshot to: results\Sem3D_Run_20250607_113842\crash_snapshot
Training finished
****EPOCH 0****
****EPOCH 0****
****EPOCH 0****
****EPOCH 0****
Numerical error at step 1
Error details: indices[30000] = 3930 is not in [0, 9)
	 [[{{node loss/GatherV2_2}} = GatherV2[Taxis=DT_INT32, Tindices=DT_INT32, Tparams=DT_INT32, _device="/job:localhost/replica:0/task:0/device:CPU:0"](loss/concat, loss/GatherV2_1, loss/GatherV2_1/axis)]]

Caused by op 'loss/GatherV2_2', defined at:
  File "main_Semantic3D.py", line 710, in <module>
    model = Network(dataset, cfg)
  File "D:\RandLA-Net\RandLANet.py", line 1304, in __init__
    self._build_loss()
  File "D:\RandLA-Net\RandLANet.py", line 1477, in _build_loss
    valid_labels = tf.gather(all_classes, init_labels)
  File "C:\Users\Ayaan\anaconda3\envs\randlanet\lib\site-packages\tensorflow\python\ops\array_ops.py", line 2669, in gather
    return gen_array_ops.gather_v2(params, indices, axis, name=name)
  File "C:\Users\Ayaan\anaconda3\envs\randlanet\lib\site-packages\tensorflow\python\ops\gen_array_ops.py", line 3866, in gather_v2
    "GatherV2", params=params, indices=indices, axis=axis, name=name)
  File "C:\Users\Ayaan\anaconda3\envs\randlanet\lib\site-packages\tensorflow\python\framework\op_def_library.py", line 787, in _apply_op_helper
    op_def=op_def)
  File "C:\Users\Ayaan\anaconda3\envs\randlanet\lib\site-packages\tensorflow\python\util\deprecation.py", line 488, in new_func
    return func(*args, **kwargs)
  File "C:\Users\Ayaan\anaconda3\envs\randlanet\lib\site-packages\tensorflow\python\framework\ops.py", line 3272, in create_op
    op_def=op_def)
  File "C:\Users\Ayaan\anaconda3\envs\randlanet\lib\site-packages\tensorflow\python\framework\ops.py", line 1768, in __init__
    self._traceback = tf_stack.extract_stack()

InvalidArgumentError (see above for traceback): indices[30000] = 3930 is not in [0, 9)
	 [[{{node loss/GatherV2_2}} = GatherV2[Taxis=DT_INT32, Tindices=DT_INT32, Tparams=DT_INT32, _device="/job:localhost/replica:0/task:0/device:CPU:0"](loss/concat, loss/GatherV2_1, loss/GatherV2_1/axis)]]

Saved crash snapshot to: results\Sem3D_Run_20250607_152017\crash_snapshot
Training finished
****EPOCH 0****
Numerical error at step 1
Error details: indices[30000] = 4067 is not in [0, 9)
	 [[{{node loss/GatherV2_2}} = GatherV2[Taxis=DT_INT32, Tindices=DT_INT32, Tparams=DT_INT32, _device="/job:localhost/replica:0/task:0/device:CPU:0"](loss/concat, loss/GatherV2_1, loss/GatherV2_1/axis)]]

Caused by op 'loss/GatherV2_2', defined at:
  File "main_Semantic3D.py", line 710, in <module>
    model = Network(dataset, cfg)
  File "D:\RandLA-Net\RandLANet.py", line 1319, in __init__
    self._build_loss()
  File "D:\RandLA-Net\RandLANet.py", line 1492, in _build_loss
    valid_labels = tf.gather(all_classes, init_labels)
  File "C:\Users\Ayaan\anaconda3\envs\randlanet\lib\site-packages\tensorflow\python\ops\array_ops.py", line 2669, in gather
    return gen_array_ops.gather_v2(params, indices, axis, name=name)
  File "C:\Users\Ayaan\anaconda3\envs\randlanet\lib\site-packages\tensorflow\python\ops\gen_array_ops.py", line 3866, in gather_v2
    "GatherV2", params=params, indices=indices, axis=axis, name=name)
  File "C:\Users\Ayaan\anaconda3\envs\randlanet\lib\site-packages\tensorflow\python\framework\op_def_library.py", line 787, in _apply_op_helper
    op_def=op_def)
  File "C:\Users\Ayaan\anaconda3\envs\randlanet\lib\site-packages\tensorflow\python\util\deprecation.py", line 488, in new_func
    return func(*args, **kwargs)
  File "C:\Users\Ayaan\anaconda3\envs\randlanet\lib\site-packages\tensorflow\python\framework\ops.py", line 3272, in create_op
    op_def=op_def)
  File "C:\Users\Ayaan\anaconda3\envs\randlanet\lib\site-packages\tensorflow\python\framework\ops.py", line 1768, in __init__
    self._traceback = tf_stack.extract_stack()

InvalidArgumentError (see above for traceback): indices[30000] = 4067 is not in [0, 9)
	 [[{{node loss/GatherV2_2}} = GatherV2[Taxis=DT_INT32, Tindices=DT_INT32, Tparams=DT_INT32, _device="/job:localhost/replica:0/task:0/device:CPU:0"](loss/concat, loss/GatherV2_1, loss/GatherV2_1/axis)]]

Saved crash snapshot to: results\Sem3D_Run_20250607_183107\crash_snapshot
Training finished
****EPOCH 0****
Numerical error at step 1
Error details: indices[30000] = 3603 is not in [0, 9)
	 [[{{node loss/GatherV2_2}} = GatherV2[Taxis=DT_INT32, Tindices=DT_INT32, Tparams=DT_INT32, _device="/job:localhost/replica:0/task:0/device:CPU:0"](loss/concat, loss/GatherV2_1, loss/GatherV2_1/axis)]]

Caused by op 'loss/GatherV2_2', defined at:
  File "main_Semantic3D.py", line 710, in <module>
    model = Network(dataset, cfg)
  File "D:\RandLA-Net\RandLANet.py", line 1325, in __init__
    self._build_loss()
  File "D:\RandLA-Net\RandLANet.py", line 1498, in _build_loss
    valid_labels = tf.gather(all_classes, init_labels)
  File "C:\Users\Ayaan\anaconda3\envs\randlanet\lib\site-packages\tensorflow\python\ops\array_ops.py", line 2669, in gather
    return gen_array_ops.gather_v2(params, indices, axis, name=name)
  File "C:\Users\Ayaan\anaconda3\envs\randlanet\lib\site-packages\tensorflow\python\ops\gen_array_ops.py", line 3866, in gather_v2
    "GatherV2", params=params, indices=indices, axis=axis, name=name)
  File "C:\Users\Ayaan\anaconda3\envs\randlanet\lib\site-packages\tensorflow\python\framework\op_def_library.py", line 787, in _apply_op_helper
    op_def=op_def)
  File "C:\Users\Ayaan\anaconda3\envs\randlanet\lib\site-packages\tensorflow\python\util\deprecation.py", line 488, in new_func
    return func(*args, **kwargs)
  File "C:\Users\Ayaan\anaconda3\envs\randlanet\lib\site-packages\tensorflow\python\framework\ops.py", line 3272, in create_op
    op_def=op_def)
  File "C:\Users\Ayaan\anaconda3\envs\randlanet\lib\site-packages\tensorflow\python\framework\ops.py", line 1768, in __init__
    self._traceback = tf_stack.extract_stack()

InvalidArgumentError (see above for traceback): indices[30000] = 3603 is not in [0, 9)
	 [[{{node loss/GatherV2_2}} = GatherV2[Taxis=DT_INT32, Tindices=DT_INT32, Tparams=DT_INT32, _device="/job:localhost/replica:0/task:0/device:CPU:0"](loss/concat, loss/GatherV2_1, loss/GatherV2_1/axis)]]

Saved crash snapshot to: results\Sem3D_Run_20250608_075349\crash_snapshot
Training finished
****EPOCH 0****
Numerical error at step 1
Error details: Input to reshape is a tensor with 1048576 values, but the requested shape has 8388608
	 [[{{node inference/Enc_LTA_0/Reshape_9}} = Reshape[T=DT_FLOAT, Tshape=DT_INT32, _device="/job:localhost/replica:0/task:0/device:CPU:0"](inference/Enc_LTA_0/Enc_LTA_0/query/BiasAdd, inference/Dec_LTA_4/Reshape_9/shape)]]

Caused by op 'inference/Enc_LTA_0/Reshape_9', defined at:
  File "main_Semantic3D.py", line 710, in <module>
    model = Network(dataset, cfg)
  File "D:\RandLA-Net\RandLANet.py", line 1320, in __init__
    self.logits = self.inference(self.inputs, self.is_training)
  File "D:\RandLA-Net\RandLANet.py", line 1384, in inference
    d_out[i], 'Enc_LTA_{}'.format(i), is_training=is_training
  File "D:\RandLA-Net\RandLANet.py", line 1239, in local_transformer_aggregation
    query_reshaped = tf.reshape(query, [B, N, heads, head_dim])            # [B, N, h, hd]
  File "C:\Users\Ayaan\anaconda3\envs\randlanet\lib\site-packages\tensorflow\python\ops\gen_array_ops.py", line 7546, in reshape
    "Reshape", tensor=tensor, shape=shape, name=name)
  File "C:\Users\Ayaan\anaconda3\envs\randlanet\lib\site-packages\tensorflow\python\framework\op_def_library.py", line 787, in _apply_op_helper
    op_def=op_def)
  File "C:\Users\Ayaan\anaconda3\envs\randlanet\lib\site-packages\tensorflow\python\util\deprecation.py", line 488, in new_func
    return func(*args, **kwargs)
  File "C:\Users\Ayaan\anaconda3\envs\randlanet\lib\site-packages\tensorflow\python\framework\ops.py", line 3272, in create_op
    op_def=op_def)
  File "C:\Users\Ayaan\anaconda3\envs\randlanet\lib\site-packages\tensorflow\python\framework\ops.py", line 1768, in __init__
    self._traceback = tf_stack.extract_stack()

InvalidArgumentError (see above for traceback): Input to reshape is a tensor with 1048576 values, but the requested shape has 8388608
	 [[{{node inference/Enc_LTA_0/Reshape_9}} = Reshape[T=DT_FLOAT, Tshape=DT_INT32, _device="/job:localhost/replica:0/task:0/device:CPU:0"](inference/Enc_LTA_0/Enc_LTA_0/query/BiasAdd, inference/Dec_LTA_4/Reshape_9/shape)]]

Saved crash snapshot to: results\Sem3D_Run_20250608_084642\crash_snapshot
Training finished
****EPOCH 0****
Numerical error at step 1
Error details: Input to reshape is a tensor with 1048576 values, but the requested shape has 8388608
	 [[{{node inference/Enc_LTA_0/Reshape_9}} = Reshape[T=DT_FLOAT, Tshape=DT_INT32, _device="/job:localhost/replica:0/task:0/device:CPU:0"](inference/Enc_LTA_0/Enc_LTA_0/query/BiasAdd, inference/Dec_LTA_4/stack_4)]]

Caused by op 'inference/Enc_LTA_0/Reshape_9', defined at:
  File "main_Semantic3D.py", line 710, in <module>
    model = Network(dataset, cfg)
  File "D:\RandLA-Net\RandLANet.py", line 1335, in __init__
    self.logits = self.inference(self.inputs, self.is_training)
  File "D:\RandLA-Net\RandLANet.py", line 1399, in inference
    d_out[i], 'Enc_LTA_{}'.format(i), is_training=is_training
  File "D:\RandLA-Net\RandLANet.py", line 1253, in local_transformer_aggregation
    tf.stack([B, N, heads, head_dim])
  File "C:\Users\Ayaan\anaconda3\envs\randlanet\lib\site-packages\tensorflow\python\ops\gen_array_ops.py", line 7546, in reshape
    "Reshape", tensor=tensor, shape=shape, name=name)
  File "C:\Users\Ayaan\anaconda3\envs\randlanet\lib\site-packages\tensorflow\python\framework\op_def_library.py", line 787, in _apply_op_helper
    op_def=op_def)
  File "C:\Users\Ayaan\anaconda3\envs\randlanet\lib\site-packages\tensorflow\python\util\deprecation.py", line 488, in new_func
    return func(*args, **kwargs)
  File "C:\Users\Ayaan\anaconda3\envs\randlanet\lib\site-packages\tensorflow\python\framework\ops.py", line 3272, in create_op
    op_def=op_def)
  File "C:\Users\Ayaan\anaconda3\envs\randlanet\lib\site-packages\tensorflow\python\framework\ops.py", line 1768, in __init__
    self._traceback = tf_stack.extract_stack()

InvalidArgumentError (see above for traceback): Input to reshape is a tensor with 1048576 values, but the requested shape has 8388608
	 [[{{node inference/Enc_LTA_0/Reshape_9}} = Reshape[T=DT_FLOAT, Tshape=DT_INT32, _device="/job:localhost/replica:0/task:0/device:CPU:0"](inference/Enc_LTA_0/Enc_LTA_0/query/BiasAdd, inference/Dec_LTA_4/stack_4)]]

Saved crash snapshot to: results\Sem3D_Run_20250608_091646\crash_snapshot
Training finished
****EPOCH 0****
Numerical error at step 1
Error details: Input to reshape is a tensor with 1048576 values, but the requested shape has 8388608
	 [[{{node inference/Enc_LTA_0/Reshape_9}} = Reshape[T=DT_FLOAT, Tshape=DT_INT32, _device="/job:localhost/replica:0/task:0/device:CPU:0"](inference/Enc_LTA_0/Enc_LTA_0/query/BiasAdd, inference/Dec_LTA_4/stack_4)]]

Caused by op 'inference/Enc_LTA_0/Reshape_9', defined at:
  File "main_Semantic3D.py", line 710, in <module>
    model = Network(dataset, cfg)
  File "D:\RandLA-Net\RandLANet.py", line 1337, in __init__
    self.logits = self.inference(self.inputs, self.is_training)
  File "D:\RandLA-Net\RandLANet.py", line 1401, in inference
    d_out[i], 'Enc_LTA_{}'.format(i), is_training=is_training
  File "D:\RandLA-Net\RandLANet.py", line 1253, in local_transformer_aggregation
    tf.stack([B, N, heads, head_dim])  # Dynamic shape
  File "C:\Users\Ayaan\anaconda3\envs\randlanet\lib\site-packages\tensorflow\python\ops\gen_array_ops.py", line 7546, in reshape
    "Reshape", tensor=tensor, shape=shape, name=name)
  File "C:\Users\Ayaan\anaconda3\envs\randlanet\lib\site-packages\tensorflow\python\framework\op_def_library.py", line 787, in _apply_op_helper
    op_def=op_def)
  File "C:\Users\Ayaan\anaconda3\envs\randlanet\lib\site-packages\tensorflow\python\util\deprecation.py", line 488, in new_func
    return func(*args, **kwargs)
  File "C:\Users\Ayaan\anaconda3\envs\randlanet\lib\site-packages\tensorflow\python\framework\ops.py", line 3272, in create_op
    op_def=op_def)
  File "C:\Users\Ayaan\anaconda3\envs\randlanet\lib\site-packages\tensorflow\python\framework\ops.py", line 1768, in __init__
    self._traceback = tf_stack.extract_stack()

InvalidArgumentError (see above for traceback): Input to reshape is a tensor with 1048576 values, but the requested shape has 8388608
	 [[{{node inference/Enc_LTA_0/Reshape_9}} = Reshape[T=DT_FLOAT, Tshape=DT_INT32, _device="/job:localhost/replica:0/task:0/device:CPU:0"](inference/Enc_LTA_0/Enc_LTA_0/query/BiasAdd, inference/Dec_LTA_4/stack_4)]]

Saved crash snapshot to: results\Sem3D_Run_20250608_103252\crash_snapshot
Training finished
****EPOCH 0****
Numerical error at step 1
Error details: Input to reshape is a tensor with 1048576 values, but the requested shape has 8388608
	 [[{{node inference/Enc_LTA_0/Reshape_9}} = Reshape[T=DT_FLOAT, Tshape=DT_INT32, _device="/job:localhost/replica:0/task:0/device:CPU:0"](inference/Enc_LTA_0/Enc_LTA_0/query/BiasAdd, inference/Dec_LTA_4/Reshape_9/shape)]]

Caused by op 'inference/Enc_LTA_0/Reshape_9', defined at:
  File "main_Semantic3D.py", line 710, in <module>
    model = Network(dataset, cfg)
  File "D:\RandLA-Net\RandLANet.py", line 1337, in __init__
    self.logits = self.inference(self.inputs, self.is_training)
  File "D:\RandLA-Net\RandLANet.py", line 1401, in inference
    d_out[i], 'Enc_LTA_{}'.format(i), is_training=is_training
  File "D:\RandLA-Net\RandLANet.py", line 1253, in local_transformer_aggregation
    [B, N, heads, head_dim]  # Directly specify dimensions
  File "C:\Users\Ayaan\anaconda3\envs\randlanet\lib\site-packages\tensorflow\python\ops\gen_array_ops.py", line 7546, in reshape
    "Reshape", tensor=tensor, shape=shape, name=name)
  File "C:\Users\Ayaan\anaconda3\envs\randlanet\lib\site-packages\tensorflow\python\framework\op_def_library.py", line 787, in _apply_op_helper
    op_def=op_def)
  File "C:\Users\Ayaan\anaconda3\envs\randlanet\lib\site-packages\tensorflow\python\util\deprecation.py", line 488, in new_func
    return func(*args, **kwargs)
  File "C:\Users\Ayaan\anaconda3\envs\randlanet\lib\site-packages\tensorflow\python\framework\ops.py", line 3272, in create_op
    op_def=op_def)
  File "C:\Users\Ayaan\anaconda3\envs\randlanet\lib\site-packages\tensorflow\python\framework\ops.py", line 1768, in __init__
    self._traceback = tf_stack.extract_stack()

InvalidArgumentError (see above for traceback): Input to reshape is a tensor with 1048576 values, but the requested shape has 8388608
	 [[{{node inference/Enc_LTA_0/Reshape_9}} = Reshape[T=DT_FLOAT, Tshape=DT_INT32, _device="/job:localhost/replica:0/task:0/device:CPU:0"](inference/Enc_LTA_0/Enc_LTA_0/query/BiasAdd, inference/Dec_LTA_4/Reshape_9/shape)]]

Saved crash snapshot to: results\Sem3D_Run_20250608_112811\crash_snapshot
Training finished
****EPOCH 0****
Numerical error at step 1
Error details: Input to reshape is a tensor with 1048576 values, but the requested shape has 8388608
	 [[{{node inference/Enc_LTA_0/Reshape_9}} = Reshape[T=DT_FLOAT, Tshape=DT_INT32, _device="/job:localhost/replica:0/task:0/device:CPU:0"](inference/Enc_LTA_0/Enc_LTA_0/query/BiasAdd, inference/Dec_LTA_4/Reshape_9/shape)]]

Caused by op 'inference/Enc_LTA_0/Reshape_9', defined at:
  File "main_Semantic3D.py", line 710, in <module>
    model = Network(dataset, cfg)
  File "D:\RandLA-Net\RandLANet.py", line 1355, in __init__
    self.logits = self.inference(self.inputs, self.is_training)
  File "D:\RandLA-Net\RandLANet.py", line 1419, in inference
    d_out[i], 'Enc_LTA_{}'.format(i), is_training=is_training
  File "D:\RandLA-Net\RandLANet.py", line 1266, in local_transformer_aggregation
    [B, N, heads, head_dim]
  File "C:\Users\Ayaan\anaconda3\envs\randlanet\lib\site-packages\tensorflow\python\ops\gen_array_ops.py", line 7546, in reshape
    "Reshape", tensor=tensor, shape=shape, name=name)
  File "C:\Users\Ayaan\anaconda3\envs\randlanet\lib\site-packages\tensorflow\python\framework\op_def_library.py", line 787, in _apply_op_helper
    op_def=op_def)
  File "C:\Users\Ayaan\anaconda3\envs\randlanet\lib\site-packages\tensorflow\python\util\deprecation.py", line 488, in new_func
    return func(*args, **kwargs)
  File "C:\Users\Ayaan\anaconda3\envs\randlanet\lib\site-packages\tensorflow\python\framework\ops.py", line 3272, in create_op
    op_def=op_def)
  File "C:\Users\Ayaan\anaconda3\envs\randlanet\lib\site-packages\tensorflow\python\framework\ops.py", line 1768, in __init__
    self._traceback = tf_stack.extract_stack()

InvalidArgumentError (see above for traceback): Input to reshape is a tensor with 1048576 values, but the requested shape has 8388608
	 [[{{node inference/Enc_LTA_0/Reshape_9}} = Reshape[T=DT_FLOAT, Tshape=DT_INT32, _device="/job:localhost/replica:0/task:0/device:CPU:0"](inference/Enc_LTA_0/Enc_LTA_0/query/BiasAdd, inference/Dec_LTA_4/Reshape_9/shape)]]

Saved crash snapshot to: results\Sem3D_Run_20250608_115808\crash_snapshot
Training finished
****EPOCH 0****
Numerical error at step 1
Error details: indices[24117248] = 495874 is not in [0, 65536)
	 [[{{node inference/Enc_LTA_0/GatherV2}} = GatherV2[Taxis=DT_INT32, Tindices=DT_INT32, Tparams=DT_FLOAT, _device="/job:localhost/replica:0/task:0/device:CPU:0"](inference/fc0/LeakyRelu, inference/Enc_LTA_0/Reshape_3, loss/GatherV2_1/axis)]]

Caused by op 'inference/Enc_LTA_0/GatherV2', defined at:
  File "main_Semantic3D.py", line 710, in <module>
    model = Network(dataset, cfg)
  File "D:\RandLA-Net\RandLANet.py", line 1339, in __init__
    self.logits = self.inference(self.inputs, self.is_training)
  File "D:\RandLA-Net\RandLANet.py", line 1403, in inference
    d_out[i], 'Enc_LTA_{}'.format(i), is_training=is_training
  File "D:\RandLA-Net\RandLANet.py", line 1218, in local_transformer_aggregation
    tf.gather(flat_feat, idx_flat),
  File "C:\Users\Ayaan\anaconda3\envs\randlanet\lib\site-packages\tensorflow\python\ops\array_ops.py", line 2669, in gather
    return gen_array_ops.gather_v2(params, indices, axis, name=name)
  File "C:\Users\Ayaan\anaconda3\envs\randlanet\lib\site-packages\tensorflow\python\ops\gen_array_ops.py", line 3866, in gather_v2
    "GatherV2", params=params, indices=indices, axis=axis, name=name)
  File "C:\Users\Ayaan\anaconda3\envs\randlanet\lib\site-packages\tensorflow\python\framework\op_def_library.py", line 787, in _apply_op_helper
    op_def=op_def)
  File "C:\Users\Ayaan\anaconda3\envs\randlanet\lib\site-packages\tensorflow\python\util\deprecation.py", line 488, in new_func
    return func(*args, **kwargs)
  File "C:\Users\Ayaan\anaconda3\envs\randlanet\lib\site-packages\tensorflow\python\framework\ops.py", line 3272, in create_op
    op_def=op_def)
  File "C:\Users\Ayaan\anaconda3\envs\randlanet\lib\site-packages\tensorflow\python\framework\ops.py", line 1768, in __init__
    self._traceback = tf_stack.extract_stack()

InvalidArgumentError (see above for traceback): indices[24117248] = 495874 is not in [0, 65536)
	 [[{{node inference/Enc_LTA_0/GatherV2}} = GatherV2[Taxis=DT_INT32, Tindices=DT_INT32, Tparams=DT_FLOAT, _device="/job:localhost/replica:0/task:0/device:CPU:0"](inference/fc0/LeakyRelu, inference/Enc_LTA_0/Reshape_3, loss/GatherV2_1/axis)]]

Saved crash snapshot to: results\Sem3D_Run_20250608_123051\crash_snapshot
Training finished
****EPOCH 0****
Numerical error at step 1
Error details: Input to reshape is a tensor with 1048576 values, but the requested shape has 8388608
	 [[{{node inference/Enc_LTA_0/Reshape_9}} = Reshape[T=DT_FLOAT, Tshape=DT_INT32, _device="/job:localhost/replica:0/task:0/device:CPU:0"](inference/Enc_LTA_0/Enc_LTA_0/query/BiasAdd, inference/Dec_LTA_4/Reshape_9/shape)]]

Caused by op 'inference/Enc_LTA_0/Reshape_9', defined at:
  File "main_Semantic3D.py", line 710, in <module>
    model = Network(dataset, cfg)
  File "D:\RandLA-Net\RandLANet.py", line 1424, in __init__
    self.logits = self.inference(self.inputs, self.is_training)
  File "D:\RandLA-Net\RandLANet.py", line 1488, in inference
    d_out[i], 'Enc_LTA_{}'.format(i), is_training=is_training
  File "D:\RandLA-Net\RandLANet.py", line 1343, in local_transformer_aggregation
    query_reshaped = tf.reshape(query,          [B, N, heads, head_dim])
  File "C:\Users\Ayaan\anaconda3\envs\randlanet\lib\site-packages\tensorflow\python\ops\gen_array_ops.py", line 7546, in reshape
    "Reshape", tensor=tensor, shape=shape, name=name)
  File "C:\Users\Ayaan\anaconda3\envs\randlanet\lib\site-packages\tensorflow\python\framework\op_def_library.py", line 787, in _apply_op_helper
    op_def=op_def)
  File "C:\Users\Ayaan\anaconda3\envs\randlanet\lib\site-packages\tensorflow\python\util\deprecation.py", line 488, in new_func
    return func(*args, **kwargs)
  File "C:\Users\Ayaan\anaconda3\envs\randlanet\lib\site-packages\tensorflow\python\framework\ops.py", line 3272, in create_op
    op_def=op_def)
  File "C:\Users\Ayaan\anaconda3\envs\randlanet\lib\site-packages\tensorflow\python\framework\ops.py", line 1768, in __init__
    self._traceback = tf_stack.extract_stack()

InvalidArgumentError (see above for traceback): Input to reshape is a tensor with 1048576 values, but the requested shape has 8388608
	 [[{{node inference/Enc_LTA_0/Reshape_9}} = Reshape[T=DT_FLOAT, Tshape=DT_INT32, _device="/job:localhost/replica:0/task:0/device:CPU:0"](inference/Enc_LTA_0/Enc_LTA_0/query/BiasAdd, inference/Dec_LTA_4/Reshape_9/shape)]]

Saved crash snapshot to: results\Sem3D_Run_20250608_125339\crash_snapshot
Training finished
****EPOCH 0****
Numerical error at step 1
Error details: indices[13631488] = 296277 is not in [0, 65536)
	 [[{{node inference/Enc_LTA_0/GatherV2}} = GatherV2[Taxis=DT_INT32, Tindices=DT_INT32, Tparams=DT_FLOAT, _device="/job:localhost/replica:0/task:0/device:CPU:0"](inference/fc0/LeakyRelu, inference/Enc_LTA_0/Reshape_1, loss/GatherV2_1/axis)]]

Caused by op 'inference/Enc_LTA_0/GatherV2', defined at:
  File "main_Semantic3D.py", line 710, in <module>
    model = Network(dataset, cfg)
  File "D:\RandLA-Net\RandLANet.py", line 1427, in __init__
    self.logits = self.inference(self.inputs, self.is_training)
  File "D:\RandLA-Net\RandLANet.py", line 1491, in inference
    d_out[i], 'Enc_LTA_{}'.format(i), is_training=is_training
  File "D:\RandLA-Net\RandLANet.py", line 1314, in local_transformer_aggregation
    neigh_feat = tf.gather(flat_feat, idx_flat)       # [B*N*k, C_in] :contentReference[oaicite:6]{index=6}
  File "C:\Users\Ayaan\anaconda3\envs\randlanet\lib\site-packages\tensorflow\python\ops\array_ops.py", line 2669, in gather
    return gen_array_ops.gather_v2(params, indices, axis, name=name)
  File "C:\Users\Ayaan\anaconda3\envs\randlanet\lib\site-packages\tensorflow\python\ops\gen_array_ops.py", line 3866, in gather_v2
    "GatherV2", params=params, indices=indices, axis=axis, name=name)
  File "C:\Users\Ayaan\anaconda3\envs\randlanet\lib\site-packages\tensorflow\python\framework\op_def_library.py", line 787, in _apply_op_helper
    op_def=op_def)
  File "C:\Users\Ayaan\anaconda3\envs\randlanet\lib\site-packages\tensorflow\python\util\deprecation.py", line 488, in new_func
    return func(*args, **kwargs)
  File "C:\Users\Ayaan\anaconda3\envs\randlanet\lib\site-packages\tensorflow\python\framework\ops.py", line 3272, in create_op
    op_def=op_def)
  File "C:\Users\Ayaan\anaconda3\envs\randlanet\lib\site-packages\tensorflow\python\framework\ops.py", line 1768, in __init__
    self._traceback = tf_stack.extract_stack()

InvalidArgumentError (see above for traceback): indices[13631488] = 296277 is not in [0, 65536)
	 [[{{node inference/Enc_LTA_0/GatherV2}} = GatherV2[Taxis=DT_INT32, Tindices=DT_INT32, Tparams=DT_FLOAT, _device="/job:localhost/replica:0/task:0/device:CPU:0"](inference/fc0/LeakyRelu, inference/Enc_LTA_0/Reshape_1, loss/GatherV2_1/axis)]]

Saved crash snapshot to: results\Sem3D_Run_20250608_132029\crash_snapshot
Training finished
****EPOCH 0****
Numerical error at step 1
Error details: indices[24641536] = 521557 is not in [0, 65536)
	 [[{{node inference/Enc_LTA_0/GatherV2}} = GatherV2[Taxis=DT_INT32, Tindices=DT_INT32, Tparams=DT_FLOAT, _device="/job:localhost/replica:0/task:0/device:CPU:0"](inference/fc0/LeakyRelu, inference/Enc_LTA_0/clip_by_value, loss/GatherV2_1/axis)]]

Caused by op 'inference/Enc_LTA_0/GatherV2', defined at:
  File "main_Semantic3D.py", line 710, in <module>
    model = Network(dataset, cfg)
  File "D:\RandLA-Net\RandLANet.py", line 1352, in __init__
    self.logits = self.inference(self.inputs, self.is_training)
  File "D:\RandLA-Net\RandLANet.py", line 1416, in inference
    d_out[i], 'Enc_LTA_{}'.format(i), is_training=is_training
  File "D:\RandLA-Net\RandLANet.py", line 1231, in local_transformer_aggregation
    tf.gather(flat_feat, idx_flat),
  File "C:\Users\Ayaan\anaconda3\envs\randlanet\lib\site-packages\tensorflow\python\ops\array_ops.py", line 2669, in gather
    return gen_array_ops.gather_v2(params, indices, axis, name=name)
  File "C:\Users\Ayaan\anaconda3\envs\randlanet\lib\site-packages\tensorflow\python\ops\gen_array_ops.py", line 3866, in gather_v2
    "GatherV2", params=params, indices=indices, axis=axis, name=name)
  File "C:\Users\Ayaan\anaconda3\envs\randlanet\lib\site-packages\tensorflow\python\framework\op_def_library.py", line 787, in _apply_op_helper
    op_def=op_def)
  File "C:\Users\Ayaan\anaconda3\envs\randlanet\lib\site-packages\tensorflow\python\util\deprecation.py", line 488, in new_func
    return func(*args, **kwargs)
  File "C:\Users\Ayaan\anaconda3\envs\randlanet\lib\site-packages\tensorflow\python\framework\ops.py", line 3272, in create_op
    op_def=op_def)
  File "C:\Users\Ayaan\anaconda3\envs\randlanet\lib\site-packages\tensorflow\python\framework\ops.py", line 1768, in __init__
    self._traceback = tf_stack.extract_stack()

InvalidArgumentError (see above for traceback): indices[24641536] = 521557 is not in [0, 65536)
	 [[{{node inference/Enc_LTA_0/GatherV2}} = GatherV2[Taxis=DT_INT32, Tindices=DT_INT32, Tparams=DT_FLOAT, _device="/job:localhost/replica:0/task:0/device:CPU:0"](inference/fc0/LeakyRelu, inference/Enc_LTA_0/clip_by_value, loss/GatherV2_1/axis)]]

Saved crash snapshot to: results\Sem3D_Run_20250608_134127\crash_snapshot
Training finished
****EPOCH 0****
Numerical error at step 1
Error details: Input to reshape is a tensor with 524288 values, but the requested shape has 4194304
	 [[{{node inference/Enc_LTA_0/Reshape}} = Reshape[T=DT_FLOAT, Tshape=DT_INT32, _class=["loc:@optimizer/gradients/inference/Enc_LTA_0/GatherV2_grad/ToInt32"], _device="/job:localhost/replica:0/task:0/device:CPU:0"](inference/Print_1, inference/Enc_LTA_0/Reshape/shape)]]

Caused by op 'inference/Enc_LTA_0/Reshape', defined at:
  File "main_Semantic3D.py", line 710, in <module>
    model = Network(dataset, cfg)
  File "D:\RandLA-Net\RandLANet.py", line 1510, in __init__
    self.logits = self.inference(self.inputs, self.is_training)
  File "D:\RandLA-Net\RandLANet.py", line 1591, in inference
    is_training=is_training
  File "D:\RandLA-Net\RandLANet.py", line 1370, in local_transformer_aggregation
    flat_feat = tf.reshape(features, [B * N, C_in])   # [B*N, C_in]
  File "C:\Users\Ayaan\anaconda3\envs\randlanet\lib\site-packages\tensorflow\python\ops\gen_array_ops.py", line 7546, in reshape
    "Reshape", tensor=tensor, shape=shape, name=name)
  File "C:\Users\Ayaan\anaconda3\envs\randlanet\lib\site-packages\tensorflow\python\framework\op_def_library.py", line 787, in _apply_op_helper
    op_def=op_def)
  File "C:\Users\Ayaan\anaconda3\envs\randlanet\lib\site-packages\tensorflow\python\util\deprecation.py", line 488, in new_func
    return func(*args, **kwargs)
  File "C:\Users\Ayaan\anaconda3\envs\randlanet\lib\site-packages\tensorflow\python\framework\ops.py", line 3272, in create_op
    op_def=op_def)
  File "C:\Users\Ayaan\anaconda3\envs\randlanet\lib\site-packages\tensorflow\python\framework\ops.py", line 1768, in __init__
    self._traceback = tf_stack.extract_stack()

InvalidArgumentError (see above for traceback): Input to reshape is a tensor with 524288 values, but the requested shape has 4194304
	 [[{{node inference/Enc_LTA_0/Reshape}} = Reshape[T=DT_FLOAT, Tshape=DT_INT32, _class=["loc:@optimizer/gradients/inference/Enc_LTA_0/GatherV2_grad/ToInt32"], _device="/job:localhost/replica:0/task:0/device:CPU:0"](inference/Print_1, inference/Enc_LTA_0/Reshape/shape)]]

Saved crash snapshot to: results\Sem3D_Run_20250609_101343\crash_snapshot
Training finished
****EPOCH 0****
Numerical error at step 1
Error details: Input to reshape is a tensor with 524288 values, but the requested shape has 4194304
	 [[{{node inference/Enc_LTA_0/Reshape}} = Reshape[T=DT_FLOAT, Tshape=DT_INT32, _class=["loc:@optimizer/gradients/inference/Enc_LTA_0/GatherV2_grad/ToInt32"], _device="/job:localhost/replica:0/task:0/device:CPU:0"](inference/Print_1, inference/Enc_LTA_0/Reshape/shape)]]

Caused by op 'inference/Enc_LTA_0/Reshape', defined at:
  File "main_Semantic3D.py", line 710, in <module>
    model = Network(dataset, cfg)
  File "D:\RandLA-Net\RandLANet.py", line 1510, in __init__
    self.logits = self.inference(self.inputs, self.is_training)
  File "D:\RandLA-Net\RandLANet.py", line 1591, in inference
    is_training=is_training
  File "D:\RandLA-Net\RandLANet.py", line 1370, in local_transformer_aggregation
    flat_feat = tf.reshape(features, [-1, C_in])   # [B*N, C_in]
  File "C:\Users\Ayaan\anaconda3\envs\randlanet\lib\site-packages\tensorflow\python\ops\gen_array_ops.py", line 7546, in reshape
    "Reshape", tensor=tensor, shape=shape, name=name)
  File "C:\Users\Ayaan\anaconda3\envs\randlanet\lib\site-packages\tensorflow\python\framework\op_def_library.py", line 787, in _apply_op_helper
    op_def=op_def)
  File "C:\Users\Ayaan\anaconda3\envs\randlanet\lib\site-packages\tensorflow\python\util\deprecation.py", line 488, in new_func
    return func(*args, **kwargs)
  File "C:\Users\Ayaan\anaconda3\envs\randlanet\lib\site-packages\tensorflow\python\framework\ops.py", line 3272, in create_op
    op_def=op_def)
  File "C:\Users\Ayaan\anaconda3\envs\randlanet\lib\site-packages\tensorflow\python\framework\ops.py", line 1768, in __init__
    self._traceback = tf_stack.extract_stack()

InvalidArgumentError (see above for traceback): Input to reshape is a tensor with 524288 values, but the requested shape has 4194304
	 [[{{node inference/Enc_LTA_0/Reshape}} = Reshape[T=DT_FLOAT, Tshape=DT_INT32, _class=["loc:@optimizer/gradients/inference/Enc_LTA_0/GatherV2_grad/ToInt32"], _device="/job:localhost/replica:0/task:0/device:CPU:0"](inference/Print_1, inference/Enc_LTA_0/Reshape/shape)]]

Saved crash snapshot to: results\Sem3D_Run_20250609_110031\crash_snapshot
Training finished
****EPOCH 0****
Numerical error at step 1
Error details: Input to reshape is a tensor with 524288 values, but the requested shape has 4194304
	 [[{{node inference/Enc_LTA_0/Reshape}} = Reshape[T=DT_FLOAT, Tshape=DT_INT32, _class=["loc:@optimizer/gradients/inference/Enc_LTA_0/GatherV2_grad/ToInt32"], _device="/job:localhost/replica:0/task:0/device:CPU:0"](inference/Print_1, inference/Enc_LTA_0/Reshape/shape)]]

Caused by op 'inference/Enc_LTA_0/Reshape', defined at:
  File "main_Semantic3D.py", line 710, in <module>
    model = Network(dataset, cfg)
  File "D:\RandLA-Net\RandLANet.py", line 1510, in __init__
    self.logits = self.inference(self.inputs, self.is_training)
  File "D:\RandLA-Net\RandLANet.py", line 1591, in inference
    is_training=is_training
  File "D:\RandLA-Net\RandLANet.py", line 1370, in local_transformer_aggregation
    flat_feat = tf.reshape(features, [B * N, C_in])   # [B*N, C_in]
  File "C:\Users\Ayaan\anaconda3\envs\randlanet\lib\site-packages\tensorflow\python\ops\gen_array_ops.py", line 7546, in reshape
    "Reshape", tensor=tensor, shape=shape, name=name)
  File "C:\Users\Ayaan\anaconda3\envs\randlanet\lib\site-packages\tensorflow\python\framework\op_def_library.py", line 787, in _apply_op_helper
    op_def=op_def)
  File "C:\Users\Ayaan\anaconda3\envs\randlanet\lib\site-packages\tensorflow\python\util\deprecation.py", line 488, in new_func
    return func(*args, **kwargs)
  File "C:\Users\Ayaan\anaconda3\envs\randlanet\lib\site-packages\tensorflow\python\framework\ops.py", line 3272, in create_op
    op_def=op_def)
  File "C:\Users\Ayaan\anaconda3\envs\randlanet\lib\site-packages\tensorflow\python\framework\ops.py", line 1768, in __init__
    self._traceback = tf_stack.extract_stack()

InvalidArgumentError (see above for traceback): Input to reshape is a tensor with 524288 values, but the requested shape has 4194304
	 [[{{node inference/Enc_LTA_0/Reshape}} = Reshape[T=DT_FLOAT, Tshape=DT_INT32, _class=["loc:@optimizer/gradients/inference/Enc_LTA_0/GatherV2_grad/ToInt32"], _device="/job:localhost/replica:0/task:0/device:CPU:0"](inference/Print_1, inference/Enc_LTA_0/Reshape/shape)]]

Saved crash snapshot to: results\Sem3D_Run_20250609_113444\crash_snapshot
Training finished
****EPOCH 0****
Numerical error at step 1
Error details: Input to reshape is a tensor with 1048576 values, but the requested shape has 8388608
	 [[{{node inference/Enc_LTA_0/Reshape_11}} = Reshape[T=DT_FLOAT, Tshape=DT_INT32, _device="/job:localhost/replica:0/task:0/device:CPU:0"](inference/Enc_LTA_0/Enc_LTA_0/query/BiasAdd, inference/Enc_LTA_0/Reshape_11/shape)]]

Caused by op 'inference/Enc_LTA_0/Reshape_11', defined at:
  File "main_Semantic3D.py", line 710, in <module>
    model = Network(dataset, cfg)
  File "D:\RandLA-Net\RandLANet.py", line 1474, in __init__
    self.logits = self.inference(self.inputs, self.is_training)
  File "D:\RandLA-Net\RandLANet.py", line 1555, in inference
    is_training=is_training
  File "D:\RandLA-Net\RandLANet.py", line 1387, in local_transformer_aggregation
    query_resh  = tf.reshape(query,          [B, N, heads, head_dim])
  File "C:\Users\Ayaan\anaconda3\envs\randlanet\lib\site-packages\tensorflow\python\ops\gen_array_ops.py", line 7546, in reshape
    "Reshape", tensor=tensor, shape=shape, name=name)
  File "C:\Users\Ayaan\anaconda3\envs\randlanet\lib\site-packages\tensorflow\python\framework\op_def_library.py", line 787, in _apply_op_helper
    op_def=op_def)
  File "C:\Users\Ayaan\anaconda3\envs\randlanet\lib\site-packages\tensorflow\python\util\deprecation.py", line 488, in new_func
    return func(*args, **kwargs)
  File "C:\Users\Ayaan\anaconda3\envs\randlanet\lib\site-packages\tensorflow\python\framework\ops.py", line 3272, in create_op
    op_def=op_def)
  File "C:\Users\Ayaan\anaconda3\envs\randlanet\lib\site-packages\tensorflow\python\framework\ops.py", line 1768, in __init__
    self._traceback = tf_stack.extract_stack()

InvalidArgumentError (see above for traceback): Input to reshape is a tensor with 1048576 values, but the requested shape has 8388608
	 [[{{node inference/Enc_LTA_0/Reshape_11}} = Reshape[T=DT_FLOAT, Tshape=DT_INT32, _device="/job:localhost/replica:0/task:0/device:CPU:0"](inference/Enc_LTA_0/Enc_LTA_0/query/BiasAdd, inference/Enc_LTA_0/Reshape_11/shape)]]

Saved crash snapshot to: results\Sem3D_Run_20250609_165315\crash_snapshot
Training finished
****EPOCH 0****
Numerical error at step 1
Error details: Input to reshape is a tensor with 1048576 values, but the requested shape has 8388608
	 [[{{node inference/Enc_LTA_0/Reshape_14}} = Reshape[T=DT_FLOAT, Tshape=DT_INT32, _device="/job:localhost/replica:0/task:0/device:CPU:0"](inference/Enc_LTA_0/Enc_LTA_0/query/BiasAdd, inference/Enc_LTA_0/Reshape_14/shape)]]

Caused by op 'inference/Enc_LTA_0/Reshape_14', defined at:
  File "main_Semantic3D.py", line 710, in <module>
    model = Network(dataset, cfg)
  File "D:\RandLA-Net\RandLANet.py", line 1478, in __init__
    self.logits = self.inference(self.inputs, self.is_training)
  File "D:\RandLA-Net\RandLANet.py", line 1559, in inference
    is_training=is_training
  File "D:\RandLA-Net\RandLANet.py", line 1391, in local_transformer_aggregation
    query_resh = tf.reshape(query_resh, [B, N, heads, head_dim])
  File "C:\Users\Ayaan\anaconda3\envs\randlanet\lib\site-packages\tensorflow\python\ops\gen_array_ops.py", line 7546, in reshape
    "Reshape", tensor=tensor, shape=shape, name=name)
  File "C:\Users\Ayaan\anaconda3\envs\randlanet\lib\site-packages\tensorflow\python\framework\op_def_library.py", line 787, in _apply_op_helper
    op_def=op_def)
  File "C:\Users\Ayaan\anaconda3\envs\randlanet\lib\site-packages\tensorflow\python\util\deprecation.py", line 488, in new_func
    return func(*args, **kwargs)
  File "C:\Users\Ayaan\anaconda3\envs\randlanet\lib\site-packages\tensorflow\python\framework\ops.py", line 3272, in create_op
    op_def=op_def)
  File "C:\Users\Ayaan\anaconda3\envs\randlanet\lib\site-packages\tensorflow\python\framework\ops.py", line 1768, in __init__
    self._traceback = tf_stack.extract_stack()

InvalidArgumentError (see above for traceback): Input to reshape is a tensor with 1048576 values, but the requested shape has 8388608
	 [[{{node inference/Enc_LTA_0/Reshape_14}} = Reshape[T=DT_FLOAT, Tshape=DT_INT32, _device="/job:localhost/replica:0/task:0/device:CPU:0"](inference/Enc_LTA_0/Enc_LTA_0/query/BiasAdd, inference/Enc_LTA_0/Reshape_14/shape)]]

Saved crash snapshot to: results\Sem3D_Run_20250609_172956\crash_snapshot
Training finished
****EPOCH 0****
Numerical error at step 1
Error details: indices[5767168] = 79189 is not in [0, 65536)
	 [[{{node inference/Enc_LTA_0/GatherV2}} = GatherV2[Taxis=DT_INT32, Tindices=DT_INT32, Tparams=DT_FLOAT, _device="/job:localhost/replica:0/task:0/device:CPU:0"](inference/Enc_LTA_0/Reshape, inference/Enc_LTA_0/clip_by_value, loss/GatherV2_1/axis)]]

Caused by op 'inference/Enc_LTA_0/GatherV2', defined at:
  File "main_Semantic3D.py", line 710, in <module>
    model = Network(dataset, cfg)
  File "D:\RandLA-Net\RandLANet.py", line 1465, in __init__
    self.logits = self.inference(self.inputs, self.is_training)
  File "D:\RandLA-Net\RandLANet.py", line 1546, in inference
    is_training=is_training
  File "D:\RandLA-Net\RandLANet.py", line 1347, in local_transformer_aggregation
    nf = tf.gather(flat_feat, idx_flat)
  File "C:\Users\Ayaan\anaconda3\envs\randlanet\lib\site-packages\tensorflow\python\ops\array_ops.py", line 2669, in gather
    return gen_array_ops.gather_v2(params, indices, axis, name=name)
  File "C:\Users\Ayaan\anaconda3\envs\randlanet\lib\site-packages\tensorflow\python\ops\gen_array_ops.py", line 3866, in gather_v2
    "GatherV2", params=params, indices=indices, axis=axis, name=name)
  File "C:\Users\Ayaan\anaconda3\envs\randlanet\lib\site-packages\tensorflow\python\framework\op_def_library.py", line 787, in _apply_op_helper
    op_def=op_def)
  File "C:\Users\Ayaan\anaconda3\envs\randlanet\lib\site-packages\tensorflow\python\util\deprecation.py", line 488, in new_func
    return func(*args, **kwargs)
  File "C:\Users\Ayaan\anaconda3\envs\randlanet\lib\site-packages\tensorflow\python\framework\ops.py", line 3272, in create_op
    op_def=op_def)
  File "C:\Users\Ayaan\anaconda3\envs\randlanet\lib\site-packages\tensorflow\python\framework\ops.py", line 1768, in __init__
    self._traceback = tf_stack.extract_stack()

InvalidArgumentError (see above for traceback): indices[5767168] = 79189 is not in [0, 65536)
	 [[{{node inference/Enc_LTA_0/GatherV2}} = GatherV2[Taxis=DT_INT32, Tindices=DT_INT32, Tparams=DT_FLOAT, _device="/job:localhost/replica:0/task:0/device:CPU:0"](inference/Enc_LTA_0/Reshape, inference/Enc_LTA_0/clip_by_value, loss/GatherV2_1/axis)]]

Saved crash snapshot to: results\Sem3D_Run_20250609_180430\crash_snapshot
Training finished
****EPOCH 0****
Numerical error at step 1
Error details: Input to reshape is a tensor with 1048576 values, but the requested shape has 8388608
	 [[{{node inference/Enc_LTA_0/Reshape_14}} = Reshape[T=DT_FLOAT, Tshape=DT_INT32, _device="/job:localhost/replica:0/task:0/device:CPU:0"](inference/Enc_LTA_0/Enc_LTA_0/query/BiasAdd, inference/Enc_LTA_0/Reshape_14/shape)]]

Caused by op 'inference/Enc_LTA_0/Reshape_14', defined at:
  File "main_Semantic3D.py", line 710, in <module>
    model = Network(dataset, cfg)
  File "D:\RandLA-Net\RandLANet.py", line 1478, in __init__
    self.logits = self.inference(self.inputs, self.is_training)
  File "D:\RandLA-Net\RandLANet.py", line 1559, in inference
    is_training=is_training
  File "D:\RandLA-Net\RandLANet.py", line 1391, in local_transformer_aggregation
    query_resh = tf.reshape(query_resh, [B, N, heads, head_dim])
  File "C:\Users\Ayaan\anaconda3\envs\randlanet\lib\site-packages\tensorflow\python\ops\gen_array_ops.py", line 7546, in reshape
    "Reshape", tensor=tensor, shape=shape, name=name)
  File "C:\Users\Ayaan\anaconda3\envs\randlanet\lib\site-packages\tensorflow\python\framework\op_def_library.py", line 787, in _apply_op_helper
    op_def=op_def)
  File "C:\Users\Ayaan\anaconda3\envs\randlanet\lib\site-packages\tensorflow\python\util\deprecation.py", line 488, in new_func
    return func(*args, **kwargs)
  File "C:\Users\Ayaan\anaconda3\envs\randlanet\lib\site-packages\tensorflow\python\framework\ops.py", line 3272, in create_op
    op_def=op_def)
  File "C:\Users\Ayaan\anaconda3\envs\randlanet\lib\site-packages\tensorflow\python\framework\ops.py", line 1768, in __init__
    self._traceback = tf_stack.extract_stack()

InvalidArgumentError (see above for traceback): Input to reshape is a tensor with 1048576 values, but the requested shape has 8388608
	 [[{{node inference/Enc_LTA_0/Reshape_14}} = Reshape[T=DT_FLOAT, Tshape=DT_INT32, _device="/job:localhost/replica:0/task:0/device:CPU:0"](inference/Enc_LTA_0/Enc_LTA_0/query/BiasAdd, inference/Enc_LTA_0/Reshape_14/shape)]]

Saved crash snapshot to: results\Sem3D_Run_20250609_183253\crash_snapshot
Training finished
****EPOCH 0****
Numerical error at step 1
Error details: indices[5767168] = 79189 is not in [0, 65536)
	 [[{{node inference/Enc_LTA_0/GatherV2}} = GatherV2[Taxis=DT_INT32, Tindices=DT_INT32, Tparams=DT_FLOAT, _device="/job:localhost/replica:0/task:0/device:CPU:0"](inference/Enc_LTA_0/Reshape, inference/Enc_LTA_0/Reshape_2, loss/GatherV2_1/axis)]]

Caused by op 'inference/Enc_LTA_0/GatherV2', defined at:
  File "main_Semantic3D.py", line 710, in <module>
    model = Network(dataset, cfg)
  File "D:\RandLA-Net\RandLANet.py", line 1477, in __init__
    self.logits = self.inference(self.inputs, self.is_training)
  File "D:\RandLA-Net\RandLANet.py", line 1558, in inference
    is_training=is_training
  File "D:\RandLA-Net\RandLANet.py", line 1358, in local_transformer_aggregation
    nf = tf.gather(flat_feat, idx_flat)
  File "C:\Users\Ayaan\anaconda3\envs\randlanet\lib\site-packages\tensorflow\python\ops\array_ops.py", line 2669, in gather
    return gen_array_ops.gather_v2(params, indices, axis, name=name)
  File "C:\Users\Ayaan\anaconda3\envs\randlanet\lib\site-packages\tensorflow\python\ops\gen_array_ops.py", line 3866, in gather_v2
    "GatherV2", params=params, indices=indices, axis=axis, name=name)
  File "C:\Users\Ayaan\anaconda3\envs\randlanet\lib\site-packages\tensorflow\python\framework\op_def_library.py", line 787, in _apply_op_helper
    op_def=op_def)
  File "C:\Users\Ayaan\anaconda3\envs\randlanet\lib\site-packages\tensorflow\python\util\deprecation.py", line 488, in new_func
    return func(*args, **kwargs)
  File "C:\Users\Ayaan\anaconda3\envs\randlanet\lib\site-packages\tensorflow\python\framework\ops.py", line 3272, in create_op
    op_def=op_def)
  File "C:\Users\Ayaan\anaconda3\envs\randlanet\lib\site-packages\tensorflow\python\framework\ops.py", line 1768, in __init__
    self._traceback = tf_stack.extract_stack()

InvalidArgumentError (see above for traceback): indices[5767168] = 79189 is not in [0, 65536)
	 [[{{node inference/Enc_LTA_0/GatherV2}} = GatherV2[Taxis=DT_INT32, Tindices=DT_INT32, Tparams=DT_FLOAT, _device="/job:localhost/replica:0/task:0/device:CPU:0"](inference/Enc_LTA_0/Reshape, inference/Enc_LTA_0/Reshape_2, loss/GatherV2_1/axis)]]

Saved crash snapshot to: results\Sem3D_Run_20250609_190640\crash_snapshot
Training finished
****EPOCH 0****
Numerical error at step 1
Error details: Input to reshape is a tensor with 1048576 values, but the requested shape has 8388608
	 [[{{node inference/Enc_LTA_0/Reshape_11}} = Reshape[T=DT_FLOAT, Tshape=DT_INT32, _device="/job:localhost/replica:0/task:0/device:CPU:0"](inference/Enc_LTA_0/Enc_LTA_0/query/BiasAdd, inference/Enc_LTA_0/Reshape_11/shape)]]

Caused by op 'inference/Enc_LTA_0/Reshape_11', defined at:
  File "main_Semantic3D.py", line 710, in <module>
    model = Network(dataset, cfg)
  File "D:\RandLA-Net\RandLANet.py", line 1482, in __init__
    self.logits = self.inference(self.inputs, self.is_training)
  File "D:\RandLA-Net\RandLANet.py", line 1563, in inference
    is_training=is_training
  File "D:\RandLA-Net\RandLANet.py", line 1391, in local_transformer_aggregation
    query_resh = tf.reshape(query,           [B, N, heads, head_dim])
  File "C:\Users\Ayaan\anaconda3\envs\randlanet\lib\site-packages\tensorflow\python\ops\gen_array_ops.py", line 7546, in reshape
    "Reshape", tensor=tensor, shape=shape, name=name)
  File "C:\Users\Ayaan\anaconda3\envs\randlanet\lib\site-packages\tensorflow\python\framework\op_def_library.py", line 787, in _apply_op_helper
    op_def=op_def)
  File "C:\Users\Ayaan\anaconda3\envs\randlanet\lib\site-packages\tensorflow\python\util\deprecation.py", line 488, in new_func
    return func(*args, **kwargs)
  File "C:\Users\Ayaan\anaconda3\envs\randlanet\lib\site-packages\tensorflow\python\framework\ops.py", line 3272, in create_op
    op_def=op_def)
  File "C:\Users\Ayaan\anaconda3\envs\randlanet\lib\site-packages\tensorflow\python\framework\ops.py", line 1768, in __init__
    self._traceback = tf_stack.extract_stack()

InvalidArgumentError (see above for traceback): Input to reshape is a tensor with 1048576 values, but the requested shape has 8388608
	 [[{{node inference/Enc_LTA_0/Reshape_11}} = Reshape[T=DT_FLOAT, Tshape=DT_INT32, _device="/job:localhost/replica:0/task:0/device:CPU:0"](inference/Enc_LTA_0/Enc_LTA_0/query/BiasAdd, inference/Enc_LTA_0/Reshape_11/shape)]]

Saved crash snapshot to: results\Sem3D_Run_20250610_050649\crash_snapshot
Training finished
****EPOCH 0****
Numerical error at step 1
Error details: Input to reshape is a tensor with 524288 values, but the requested shape has 4194304
	 [[{{node inference/Enc_LTA_0/Reshape}} = Reshape[T=DT_FLOAT, Tshape=DT_INT32, _class=["loc:@optimizer/gradients/inference/Enc_LTA_0/GatherV2_grad/ToInt32"], _device="/job:localhost/replica:0/task:0/device:CPU:0"](inference/Print_1, inference/Enc_LTA_0/Reshape/shape)]]

Caused by op 'inference/Enc_LTA_0/Reshape', defined at:
  File "main_Semantic3D.py", line 710, in <module>
    model = Network(dataset, cfg)
  File "D:\RandLA-Net\RandLANet.py", line 1482, in __init__
    self.logits = self.inference(self.inputs, self.is_training)
  File "D:\RandLA-Net\RandLANet.py", line 1563, in inference
    is_training=is_training
  File "D:\RandLA-Net\RandLANet.py", line 1338, in local_transformer_aggregation
    flat_feat = tf.reshape(features, [B*N, C_in])
  File "C:\Users\Ayaan\anaconda3\envs\randlanet\lib\site-packages\tensorflow\python\ops\gen_array_ops.py", line 7546, in reshape
    "Reshape", tensor=tensor, shape=shape, name=name)
  File "C:\Users\Ayaan\anaconda3\envs\randlanet\lib\site-packages\tensorflow\python\framework\op_def_library.py", line 787, in _apply_op_helper
    op_def=op_def)
  File "C:\Users\Ayaan\anaconda3\envs\randlanet\lib\site-packages\tensorflow\python\util\deprecation.py", line 488, in new_func
    return func(*args, **kwargs)
  File "C:\Users\Ayaan\anaconda3\envs\randlanet\lib\site-packages\tensorflow\python\framework\ops.py", line 3272, in create_op
    op_def=op_def)
  File "C:\Users\Ayaan\anaconda3\envs\randlanet\lib\site-packages\tensorflow\python\framework\ops.py", line 1768, in __init__
    self._traceback = tf_stack.extract_stack()

InvalidArgumentError (see above for traceback): Input to reshape is a tensor with 524288 values, but the requested shape has 4194304
	 [[{{node inference/Enc_LTA_0/Reshape}} = Reshape[T=DT_FLOAT, Tshape=DT_INT32, _class=["loc:@optimizer/gradients/inference/Enc_LTA_0/GatherV2_grad/ToInt32"], _device="/job:localhost/replica:0/task:0/device:CPU:0"](inference/Print_1, inference/Enc_LTA_0/Reshape/shape)]]

Saved crash snapshot to: results\Sem3D_Run_20250610_054243\crash_snapshot
Training finished
****EPOCH 0****
Numerical error at step 1
Error details: Input to reshape is a tensor with 1048576 values, but the requested shape has 8388608
	 [[{{node inference/Enc_LTA_0/Reshape_11}} = Reshape[T=DT_FLOAT, Tshape=DT_INT32, _device="/job:localhost/replica:0/task:0/device:CPU:0"](inference/Enc_LTA_0/Enc_LTA_0/query/BiasAdd, inference/Dec_LTA_4/Reshape_11/shape)]]

Caused by op 'inference/Enc_LTA_0/Reshape_11', defined at:
  File "main_Semantic3D.py", line 710, in <module>
    model = Network(dataset, cfg)
  File "D:\RandLA-Net\RandLANet.py", line 1482, in __init__
    self.logits = self.inference(self.inputs, self.is_training)
  File "D:\RandLA-Net\RandLANet.py", line 1563, in inference
    is_training=is_training
  File "D:\RandLA-Net\RandLANet.py", line 1391, in local_transformer_aggregation
    query_resh = tf.reshape(query,           [B, N, heads, head_dim])
  File "C:\Users\Ayaan\anaconda3\envs\randlanet\lib\site-packages\tensorflow\python\ops\gen_array_ops.py", line 7546, in reshape
    "Reshape", tensor=tensor, shape=shape, name=name)
  File "C:\Users\Ayaan\anaconda3\envs\randlanet\lib\site-packages\tensorflow\python\framework\op_def_library.py", line 787, in _apply_op_helper
    op_def=op_def)
  File "C:\Users\Ayaan\anaconda3\envs\randlanet\lib\site-packages\tensorflow\python\util\deprecation.py", line 488, in new_func
    return func(*args, **kwargs)
  File "C:\Users\Ayaan\anaconda3\envs\randlanet\lib\site-packages\tensorflow\python\framework\ops.py", line 3272, in create_op
    op_def=op_def)
  File "C:\Users\Ayaan\anaconda3\envs\randlanet\lib\site-packages\tensorflow\python\framework\ops.py", line 1768, in __init__
    self._traceback = tf_stack.extract_stack()

InvalidArgumentError (see above for traceback): Input to reshape is a tensor with 1048576 values, but the requested shape has 8388608
	 [[{{node inference/Enc_LTA_0/Reshape_11}} = Reshape[T=DT_FLOAT, Tshape=DT_INT32, _device="/job:localhost/replica:0/task:0/device:CPU:0"](inference/Enc_LTA_0/Enc_LTA_0/query/BiasAdd, inference/Dec_LTA_4/Reshape_11/shape)]]

Saved crash snapshot to: results\Sem3D_Run_20250610_061732\crash_snapshot
Training finished
****EPOCH 0****
Numerical error at step 1
Error details: indices[12058624] = 226645 is not in [0, 65536)
	 [[{{node inference/Enc_LTA_0/GatherV2}} = GatherV2[Taxis=DT_INT32, Tindices=DT_INT32, Tparams=DT_FLOAT, _device="/job:localhost/replica:0/task:0/device:CPU:0"](inference/fc0/LeakyRelu, inference/Enc_LTA_0/clip_by_value, loss/GatherV2_1/axis)]]

Caused by op 'inference/Enc_LTA_0/GatherV2', defined at:
  File "main_Semantic3D.py", line 710, in <module>
    model = Network(dataset, cfg)
  File "D:\RandLA-Net\RandLANet.py", line 1392, in __init__
    self.logits = self.inference(self.inputs, self.is_training)
  File "D:\RandLA-Net\RandLANet.py", line 1473, in inference
    is_training=is_training
  File "D:\RandLA-Net\RandLANet.py", line 1251, in local_transformer_aggregation
    nf = tf.gather(flat_feat, idx_flat)           # [B*N*k, C_in]
  File "C:\Users\Ayaan\anaconda3\envs\randlanet\lib\site-packages\tensorflow\python\ops\array_ops.py", line 2669, in gather
    return gen_array_ops.gather_v2(params, indices, axis, name=name)
  File "C:\Users\Ayaan\anaconda3\envs\randlanet\lib\site-packages\tensorflow\python\ops\gen_array_ops.py", line 3866, in gather_v2
    "GatherV2", params=params, indices=indices, axis=axis, name=name)
  File "C:\Users\Ayaan\anaconda3\envs\randlanet\lib\site-packages\tensorflow\python\framework\op_def_library.py", line 787, in _apply_op_helper
    op_def=op_def)
  File "C:\Users\Ayaan\anaconda3\envs\randlanet\lib\site-packages\tensorflow\python\util\deprecation.py", line 488, in new_func
    return func(*args, **kwargs)
  File "C:\Users\Ayaan\anaconda3\envs\randlanet\lib\site-packages\tensorflow\python\framework\ops.py", line 3272, in create_op
    op_def=op_def)
  File "C:\Users\Ayaan\anaconda3\envs\randlanet\lib\site-packages\tensorflow\python\framework\ops.py", line 1768, in __init__
    self._traceback = tf_stack.extract_stack()

InvalidArgumentError (see above for traceback): indices[12058624] = 226645 is not in [0, 65536)
	 [[{{node inference/Enc_LTA_0/GatherV2}} = GatherV2[Taxis=DT_INT32, Tindices=DT_INT32, Tparams=DT_FLOAT, _device="/job:localhost/replica:0/task:0/device:CPU:0"](inference/fc0/LeakyRelu, inference/Enc_LTA_0/clip_by_value, loss/GatherV2_1/axis)]]

Saved crash snapshot to: results\Sem3D_Run_20250610_070840\crash_snapshot
Training finished
****EPOCH 0****
Numerical error at step 1
Error details: indices[24641536] = 521557 is not in [0, 65536)
	 [[{{node inference/Enc_LTA_0/GatherV2}} = GatherV2[Taxis=DT_INT32, Tindices=DT_INT32, Tparams=DT_FLOAT, _device="/job:localhost/replica:0/task:0/device:CPU:0"](inference/fc0/LeakyRelu, inference/Enc_LTA_0/clip_by_value, loss/GatherV2_1/axis)]]

Caused by op 'inference/Enc_LTA_0/GatherV2', defined at:
  File "main_Semantic3D.py", line 710, in <module>
    model = Network(dataset, cfg)
  File "D:\RandLA-Net\RandLANet.py", line 1384, in __init__
    self.logits = self.inference(self.inputs, self.is_training)
  File "D:\RandLA-Net\RandLANet.py", line 1465, in inference
    is_training=is_training
  File "D:\RandLA-Net\RandLANet.py", line 1255, in local_transformer_aggregation
    nf = tf.gather(flat_feat, idx_flat)      # [B*N*k, C_in]
  File "C:\Users\Ayaan\anaconda3\envs\randlanet\lib\site-packages\tensorflow\python\ops\array_ops.py", line 2669, in gather
    return gen_array_ops.gather_v2(params, indices, axis, name=name)
  File "C:\Users\Ayaan\anaconda3\envs\randlanet\lib\site-packages\tensorflow\python\ops\gen_array_ops.py", line 3866, in gather_v2
    "GatherV2", params=params, indices=indices, axis=axis, name=name)
  File "C:\Users\Ayaan\anaconda3\envs\randlanet\lib\site-packages\tensorflow\python\framework\op_def_library.py", line 787, in _apply_op_helper
    op_def=op_def)
  File "C:\Users\Ayaan\anaconda3\envs\randlanet\lib\site-packages\tensorflow\python\util\deprecation.py", line 488, in new_func
    return func(*args, **kwargs)
  File "C:\Users\Ayaan\anaconda3\envs\randlanet\lib\site-packages\tensorflow\python\framework\ops.py", line 3272, in create_op
    op_def=op_def)
  File "C:\Users\Ayaan\anaconda3\envs\randlanet\lib\site-packages\tensorflow\python\framework\ops.py", line 1768, in __init__
    self._traceback = tf_stack.extract_stack()

InvalidArgumentError (see above for traceback): indices[24641536] = 521557 is not in [0, 65536)
	 [[{{node inference/Enc_LTA_0/GatherV2}} = GatherV2[Taxis=DT_INT32, Tindices=DT_INT32, Tparams=DT_FLOAT, _device="/job:localhost/replica:0/task:0/device:CPU:0"](inference/fc0/LeakyRelu, inference/Enc_LTA_0/clip_by_value, loss/GatherV2_1/axis)]]

Saved crash snapshot to: results\Sem3D_Run_20250610_073728\crash_snapshot
Training finished
****EPOCH 0****
Numerical error at step 1
Error details: indices[12058624] = 251221 is not in [0, 65536)
	 [[{{node inference/Enc_LTA_0/GatherV2}} = GatherV2[Taxis=DT_INT32, Tindices=DT_INT32, Tparams=DT_FLOAT, _device="/job:localhost/replica:0/task:0/device:CPU:0"](inference/fc0/LeakyRelu, inference/Enc_LTA_0/clip_by_value, loss/GatherV2_1/axis)]]

Caused by op 'inference/Enc_LTA_0/GatherV2', defined at:
  File "main_Semantic3D.py", line 710, in <module>
    model = Network(dataset, cfg)
  File "D:\RandLA-Net\RandLANet.py", line 1498, in __init__
    self.logits = self.inference(self.inputs, self.is_training)
  File "D:\RandLA-Net\RandLANet.py", line 1579, in inference
    is_training=is_training
  File "D:\RandLA-Net\RandLANet.py", line 1369, in local_transformer_aggregation
    nf = tf.gather(flat_feat, idx_flat)      # [B*N*k, C_in]
  File "C:\Users\Ayaan\anaconda3\envs\randlanet\lib\site-packages\tensorflow\python\ops\array_ops.py", line 2669, in gather
    return gen_array_ops.gather_v2(params, indices, axis, name=name)
  File "C:\Users\Ayaan\anaconda3\envs\randlanet\lib\site-packages\tensorflow\python\ops\gen_array_ops.py", line 3866, in gather_v2
    "GatherV2", params=params, indices=indices, axis=axis, name=name)
  File "C:\Users\Ayaan\anaconda3\envs\randlanet\lib\site-packages\tensorflow\python\framework\op_def_library.py", line 787, in _apply_op_helper
    op_def=op_def)
  File "C:\Users\Ayaan\anaconda3\envs\randlanet\lib\site-packages\tensorflow\python\util\deprecation.py", line 488, in new_func
    return func(*args, **kwargs)
  File "C:\Users\Ayaan\anaconda3\envs\randlanet\lib\site-packages\tensorflow\python\framework\ops.py", line 3272, in create_op
    op_def=op_def)
  File "C:\Users\Ayaan\anaconda3\envs\randlanet\lib\site-packages\tensorflow\python\framework\ops.py", line 1768, in __init__
    self._traceback = tf_stack.extract_stack()

InvalidArgumentError (see above for traceback): indices[12058624] = 251221 is not in [0, 65536)
	 [[{{node inference/Enc_LTA_0/GatherV2}} = GatherV2[Taxis=DT_INT32, Tindices=DT_INT32, Tparams=DT_FLOAT, _device="/job:localhost/replica:0/task:0/device:CPU:0"](inference/fc0/LeakyRelu, inference/Enc_LTA_0/clip_by_value, loss/GatherV2_1/axis)]]

Saved crash snapshot to: results\Sem3D_Run_20250610_081139\crash_snapshot
Training finished
****EPOCH 0****
Numerical error at step 1
Error details: Input to reshape is a tensor with 1572864 values, but the requested shape has 196608
	 [[{{node inference/Reshape_3}} = Reshape[T=DT_FLOAT, Tshape=DT_INT32, _device="/job:localhost/replica:0/task:0/device:CPU:0"](IteratorGetNext, inference/Reshape_3/shape)]]

Caused by op 'inference/Reshape_3', defined at:
  File "main_Semantic3D.py", line 710, in <module>
    model = Network(dataset, cfg)
  File "D:\RandLA-Net\RandLANet.py", line 1480, in __init__
    self.logits = self.inference(self.inputs, self.is_training)
  File "D:\RandLA-Net\RandLANet.py", line 1551, in inference
    neigh_xyz, neigh_feat = multi_scale_group(xyz_i, feat_i, neigh_idx_k1, neigh_idx_k2)
  File "D:\RandLA-Net\RandLANet.py", line 1235, in multi_scale_group
    flat_xyz  = tf.reshape(xyz,      [B * N, 3])  # [B*N, 3]
  File "C:\Users\Ayaan\anaconda3\envs\randlanet\lib\site-packages\tensorflow\python\ops\gen_array_ops.py", line 7546, in reshape
    "Reshape", tensor=tensor, shape=shape, name=name)
  File "C:\Users\Ayaan\anaconda3\envs\randlanet\lib\site-packages\tensorflow\python\framework\op_def_library.py", line 787, in _apply_op_helper
    op_def=op_def)
  File "C:\Users\Ayaan\anaconda3\envs\randlanet\lib\site-packages\tensorflow\python\util\deprecation.py", line 488, in new_func
    return func(*args, **kwargs)
  File "C:\Users\Ayaan\anaconda3\envs\randlanet\lib\site-packages\tensorflow\python\framework\ops.py", line 3272, in create_op
    op_def=op_def)
  File "C:\Users\Ayaan\anaconda3\envs\randlanet\lib\site-packages\tensorflow\python\framework\ops.py", line 1768, in __init__
    self._traceback = tf_stack.extract_stack()

InvalidArgumentError (see above for traceback): Input to reshape is a tensor with 1572864 values, but the requested shape has 196608
	 [[{{node inference/Reshape_3}} = Reshape[T=DT_FLOAT, Tshape=DT_INT32, _device="/job:localhost/replica:0/task:0/device:CPU:0"](IteratorGetNext, inference/Reshape_3/shape)]]

Saved crash snapshot to: results\Sem3D_Run_20250610_085102\crash_snapshot
Training finished
****EPOCH 0****
Numerical error at step 1
Error details: Input to reshape is a tensor with 1572864 values, but the requested shape has 196608
	 [[{{node inference/Reshape_3}} = Reshape[T=DT_FLOAT, Tshape=DT_INT32, _device="/job:localhost/replica:0/task:0/device:CPU:0"](IteratorGetNext, inference/Reshape_3/shape)]]

Caused by op 'inference/Reshape_3', defined at:
  File "main_Semantic3D.py", line 710, in <module>
    model = Network(dataset, cfg)
  File "D:\RandLA-Net\RandLANet.py", line 1480, in __init__
    self.logits = self.inference(self.inputs, self.is_training)
  File "D:\RandLA-Net\RandLANet.py", line 1571, in inference
    neigh_xyz, neigh_feat = multi_scale_group(xyz_i, feat_i, neigh_idx_k1, neigh_idx_k2)
  File "D:\RandLA-Net\RandLANet.py", line 1235, in multi_scale_group
    flat_xyz  = tf.reshape(xyz,      [B * N, 3])  # [B*N, 3]
  File "C:\Users\Ayaan\anaconda3\envs\randlanet\lib\site-packages\tensorflow\python\ops\gen_array_ops.py", line 7546, in reshape
    "Reshape", tensor=tensor, shape=shape, name=name)
  File "C:\Users\Ayaan\anaconda3\envs\randlanet\lib\site-packages\tensorflow\python\framework\op_def_library.py", line 787, in _apply_op_helper
    op_def=op_def)
  File "C:\Users\Ayaan\anaconda3\envs\randlanet\lib\site-packages\tensorflow\python\util\deprecation.py", line 488, in new_func
    return func(*args, **kwargs)
  File "C:\Users\Ayaan\anaconda3\envs\randlanet\lib\site-packages\tensorflow\python\framework\ops.py", line 3272, in create_op
    op_def=op_def)
  File "C:\Users\Ayaan\anaconda3\envs\randlanet\lib\site-packages\tensorflow\python\framework\ops.py", line 1768, in __init__
    self._traceback = tf_stack.extract_stack()

InvalidArgumentError (see above for traceback): Input to reshape is a tensor with 1572864 values, but the requested shape has 196608
	 [[{{node inference/Reshape_3}} = Reshape[T=DT_FLOAT, Tshape=DT_INT32, _device="/job:localhost/replica:0/task:0/device:CPU:0"](IteratorGetNext, inference/Reshape_3/shape)]]

Saved crash snapshot to: results\Sem3D_Run_20250610_093226\crash_snapshot
Training finished
****EPOCH 0****
Numerical error at step 1
Error details: Input to reshape is a tensor with 1572864 values, but the requested shape has 196608
	 [[{{node inference/Reshape_3}} = Reshape[T=DT_FLOAT, Tshape=DT_INT32, _device="/job:localhost/replica:0/task:0/device:CPU:0"](IteratorGetNext, inference/Reshape_3/shape)]]

Caused by op 'inference/Reshape_3', defined at:
  File "main_Semantic3D.py", line 710, in <module>
    model = Network(dataset, cfg)
  File "D:\RandLA-Net\RandLANet.py", line 1480, in __init__
    self.logits = self.inference(self.inputs, self.is_training)
  File "D:\RandLA-Net\RandLANet.py", line 1579, in inference
    neigh_xyz, neigh_feat = multi_scale_group(xyz_i, feat_i, neigh_idx_k1, neigh_idx_k2)
  File "D:\RandLA-Net\RandLANet.py", line 1235, in multi_scale_group
    flat_xyz  = tf.reshape(xyz,      [B * N, 3])  # [B*N, 3]
  File "C:\Users\Ayaan\anaconda3\envs\randlanet\lib\site-packages\tensorflow\python\ops\gen_array_ops.py", line 7546, in reshape
    "Reshape", tensor=tensor, shape=shape, name=name)
  File "C:\Users\Ayaan\anaconda3\envs\randlanet\lib\site-packages\tensorflow\python\framework\op_def_library.py", line 787, in _apply_op_helper
    op_def=op_def)
  File "C:\Users\Ayaan\anaconda3\envs\randlanet\lib\site-packages\tensorflow\python\util\deprecation.py", line 488, in new_func
    return func(*args, **kwargs)
  File "C:\Users\Ayaan\anaconda3\envs\randlanet\lib\site-packages\tensorflow\python\framework\ops.py", line 3272, in create_op
    op_def=op_def)
  File "C:\Users\Ayaan\anaconda3\envs\randlanet\lib\site-packages\tensorflow\python\framework\ops.py", line 1768, in __init__
    self._traceback = tf_stack.extract_stack()

InvalidArgumentError (see above for traceback): Input to reshape is a tensor with 1572864 values, but the requested shape has 196608
	 [[{{node inference/Reshape_3}} = Reshape[T=DT_FLOAT, Tshape=DT_INT32, _device="/job:localhost/replica:0/task:0/device:CPU:0"](IteratorGetNext, inference/Reshape_3/shape)]]

Saved crash snapshot to: results\Sem3D_Run_20250610_100655\crash_snapshot
Training finished
****EPOCH 0****
Numerical error at step 1
Error details: Input to reshape is a tensor with 1572864 values, but the requested shape has 196608
	 [[{{node inference/Reshape_3}} = Reshape[T=DT_FLOAT, Tshape=DT_INT32, _device="/job:localhost/replica:0/task:0/device:CPU:0"](IteratorGetNext, inference/Reshape_3/shape)]]

Caused by op 'inference/Reshape_3', defined at:
  File "main_Semantic3D.py", line 742, in <module>
    model = Network(dataset, cfg)
  File "D:\RandLA-Net\RandLANet.py", line 1480, in __init__
    self.logits = self.inference(self.inputs, self.is_training)
  File "D:\RandLA-Net\RandLANet.py", line 1579, in inference
    neigh_xyz, neigh_feat = multi_scale_group(xyz_i, feat_i, neigh_idx_k1, neigh_idx_k2)
  File "D:\RandLA-Net\RandLANet.py", line 1235, in multi_scale_group
    flat_xyz  = tf.reshape(xyz,      [B * N, 3])  # [B*N, 3]
  File "C:\Users\Ayaan\anaconda3\envs\randlanet\lib\site-packages\tensorflow\python\ops\gen_array_ops.py", line 7546, in reshape
    "Reshape", tensor=tensor, shape=shape, name=name)
  File "C:\Users\Ayaan\anaconda3\envs\randlanet\lib\site-packages\tensorflow\python\framework\op_def_library.py", line 787, in _apply_op_helper
    op_def=op_def)
  File "C:\Users\Ayaan\anaconda3\envs\randlanet\lib\site-packages\tensorflow\python\util\deprecation.py", line 488, in new_func
    return func(*args, **kwargs)
  File "C:\Users\Ayaan\anaconda3\envs\randlanet\lib\site-packages\tensorflow\python\framework\ops.py", line 3272, in create_op
    op_def=op_def)
  File "C:\Users\Ayaan\anaconda3\envs\randlanet\lib\site-packages\tensorflow\python\framework\ops.py", line 1768, in __init__
    self._traceback = tf_stack.extract_stack()

InvalidArgumentError (see above for traceback): Input to reshape is a tensor with 1572864 values, but the requested shape has 196608
	 [[{{node inference/Reshape_3}} = Reshape[T=DT_FLOAT, Tshape=DT_INT32, _device="/job:localhost/replica:0/task:0/device:CPU:0"](IteratorGetNext, inference/Reshape_3/shape)]]

Saved crash snapshot to: results\Sem3D_Run_20250610_112552\crash_snapshot
Training finished
****EPOCH 0****
Numerical error at step 1
Error details: Input to reshape is a tensor with 262144 values, but the requested shape has 1048576
	 [[{{node inference/Reshape_58}} = Reshape[T=DT_INT32, Tshape=DT_INT32, _device="/job:localhost/replica:0/task:0/device:CPU:0"](inference/transpose_7, inference/Reshape_58/shape)]]

Caused by op 'inference/Reshape_58', defined at:
  File "main_Semantic3D.py", line 742, in <module>
    model = Network(dataset, cfg)
  File "D:\RandLA-Net\RandLANet.py", line 1480, in __init__
    self.logits = self.inference(self.inputs, self.is_training)
  File "D:\RandLA-Net\RandLANet.py", line 1573, in inference
    neigh_idx_k2 = knn_blocked(xyz_i, k2, block_size=4096)
  File "D:\RandLA-Net\RandLANet.py", line 1213, in knn_blocked
    result_padded = tf.reshape(idx_blocks_transposed, [B, num_blocks * block_size, k])
  File "C:\Users\Ayaan\anaconda3\envs\randlanet\lib\site-packages\tensorflow\python\ops\gen_array_ops.py", line 7546, in reshape
    "Reshape", tensor=tensor, shape=shape, name=name)
  File "C:\Users\Ayaan\anaconda3\envs\randlanet\lib\site-packages\tensorflow\python\framework\op_def_library.py", line 787, in _apply_op_helper
    op_def=op_def)
  File "C:\Users\Ayaan\anaconda3\envs\randlanet\lib\site-packages\tensorflow\python\util\deprecation.py", line 488, in new_func
    return func(*args, **kwargs)
  File "C:\Users\Ayaan\anaconda3\envs\randlanet\lib\site-packages\tensorflow\python\framework\ops.py", line 3272, in create_op
    op_def=op_def)
  File "C:\Users\Ayaan\anaconda3\envs\randlanet\lib\site-packages\tensorflow\python\framework\ops.py", line 1768, in __init__
    self._traceback = tf_stack.extract_stack()

InvalidArgumentError (see above for traceback): Input to reshape is a tensor with 262144 values, but the requested shape has 1048576
	 [[{{node inference/Reshape_58}} = Reshape[T=DT_INT32, Tshape=DT_INT32, _device="/job:localhost/replica:0/task:0/device:CPU:0"](inference/transpose_7, inference/Reshape_58/shape)]]

Saved crash snapshot to: results\Sem3D_Run_20250610_193222\crash_snapshot
Training finished
****EPOCH 0****
Numerical error at step 1
Error details: Input to reshape is a tensor with 131072 values, but the requested shape has 524288
	 [[{{node inference/Reshape_57}} = Reshape[T=DT_INT32, Tshape=DT_INT32, _device="/job:localhost/replica:0/task:0/device:CPU:0"](inference/transpose_6, inference/Reshape_57/shape)]]

Caused by op 'inference/Reshape_57', defined at:
  File "main_Semantic3D.py", line 742, in <module>
    model = Network(dataset, cfg)
  File "D:\RandLA-Net\RandLANet.py", line 1480, in __init__
    self.logits = self.inference(self.inputs, self.is_training)
  File "D:\RandLA-Net\RandLANet.py", line 1572, in inference
    neigh_idx_k1 = knn_blocked(xyz_i, k1, block_size=4096)
  File "D:\RandLA-Net\RandLANet.py", line 1213, in knn_blocked
    result_padded = tf.reshape(idx_blocks_transposed, [B, num_blocks * block_size, k])
  File "C:\Users\Ayaan\anaconda3\envs\randlanet\lib\site-packages\tensorflow\python\ops\gen_array_ops.py", line 7546, in reshape
    "Reshape", tensor=tensor, shape=shape, name=name)
  File "C:\Users\Ayaan\anaconda3\envs\randlanet\lib\site-packages\tensorflow\python\framework\op_def_library.py", line 787, in _apply_op_helper
    op_def=op_def)
  File "C:\Users\Ayaan\anaconda3\envs\randlanet\lib\site-packages\tensorflow\python\util\deprecation.py", line 488, in new_func
    return func(*args, **kwargs)
  File "C:\Users\Ayaan\anaconda3\envs\randlanet\lib\site-packages\tensorflow\python\framework\ops.py", line 3272, in create_op
    op_def=op_def)
  File "C:\Users\Ayaan\anaconda3\envs\randlanet\lib\site-packages\tensorflow\python\framework\ops.py", line 1768, in __init__
    self._traceback = tf_stack.extract_stack()

InvalidArgumentError (see above for traceback): Input to reshape is a tensor with 131072 values, but the requested shape has 524288
	 [[{{node inference/Reshape_57}} = Reshape[T=DT_INT32, Tshape=DT_INT32, _device="/job:localhost/replica:0/task:0/device:CPU:0"](inference/transpose_6, inference/Reshape_57/shape)]]

Saved crash snapshot to: results\Sem3D_Run_20250611_055505\crash_snapshot
Training finished
****EPOCH 0****
****EPOCH 0****
****EPOCH 0****
Numerical error at step 1
Error details: indices[174784] = 3244 is not in [0, 1024)
	 [[{{node inference/Dec_LTA_0/GatherV2_1}} = GatherV2[Taxis=DT_INT32, Tindices=DT_INT32, Tparams=DT_FLOAT, _device="/job:localhost/replica:0/task:0/device:CPU:0"](inference/Dec_LTA_0/Reshape, inference/Dec_LTA_0/Reshape_3, loss/GatherV2_1/axis)]]

Caused by op 'inference/Dec_LTA_0/GatherV2_1', defined at:
  File "main_Semantic3D.py", line 742, in <module>
    model = Network(dataset, cfg)
  File "D:\RandLA-Net\RandLANet.py", line 1367, in __init__
    self.logits = self.inference(self.inputs, self.is_training)
  File "D:\RandLA-Net\RandLANet.py", line 1578, in inference
    dec_neigh_xyz, dec_neigh_feat = multi_scale_group(skip_xyz, feat_dec, skip_neigh_idx_k1, skip_neigh_idx_k1)
  File "D:\RandLA-Net\RandLANet.py", line 1128, in multi_scale_group
    nfeat1 = tf.reshape(tf.gather(flat_feat, idx1), [B, N, -1, C])
  File "C:\Users\Ayaan\anaconda3\envs\randlanet\lib\site-packages\tensorflow\python\ops\array_ops.py", line 2669, in gather
    return gen_array_ops.gather_v2(params, indices, axis, name=name)
  File "C:\Users\Ayaan\anaconda3\envs\randlanet\lib\site-packages\tensorflow\python\ops\gen_array_ops.py", line 3866, in gather_v2
    "GatherV2", params=params, indices=indices, axis=axis, name=name)
  File "C:\Users\Ayaan\anaconda3\envs\randlanet\lib\site-packages\tensorflow\python\framework\op_def_library.py", line 787, in _apply_op_helper
    op_def=op_def)
  File "C:\Users\Ayaan\anaconda3\envs\randlanet\lib\site-packages\tensorflow\python\util\deprecation.py", line 488, in new_func
    return func(*args, **kwargs)
  File "C:\Users\Ayaan\anaconda3\envs\randlanet\lib\site-packages\tensorflow\python\framework\ops.py", line 3272, in create_op
    op_def=op_def)
  File "C:\Users\Ayaan\anaconda3\envs\randlanet\lib\site-packages\tensorflow\python\framework\ops.py", line 1768, in __init__
    self._traceback = tf_stack.extract_stack()

InvalidArgumentError (see above for traceback): indices[174784] = 3244 is not in [0, 1024)
	 [[{{node inference/Dec_LTA_0/GatherV2_1}} = GatherV2[Taxis=DT_INT32, Tindices=DT_INT32, Tparams=DT_FLOAT, _device="/job:localhost/replica:0/task:0/device:CPU:0"](inference/Dec_LTA_0/Reshape, inference/Dec_LTA_0/Reshape_3, loss/GatherV2_1/axis)]]

Saved crash snapshot to: results\Sem3D_Run_20250611_080420\crash_snapshot
Training finished
****EPOCH 0****
Numerical error at step 1
Error details: Shapes of all inputs must match: values[0].shape = [4,16384,16] != values[1].shape = [4,65536,16]
	 [[{{node inference/Dec_LTA_3/stack}} = Pack[N=2, T=DT_INT32, axis=-1, _device="/job:localhost/replica:0/task:0/device:CPU:0"](inference/Dec_LTA_3/Tile_1, inference/clip_by_value)]]

Caused by op 'inference/Dec_LTA_3/stack', defined at:
  File "main_Semantic3D.py", line 742, in <module>
    model = Network(dataset, cfg)
  File "D:\RandLA-Net\RandLANet.py", line 1371, in __init__
    self.logits = self.inference(self.inputs, self.is_training)
  File "D:\RandLA-Net\RandLANet.py", line 1582, in inference
    dec_neigh_xyz, dec_neigh_feat = multi_scale_group(skip_xyz, feat_dec, skip_neigh_idx_k1, skip_neigh_idx_k1)
  File "D:\RandLA-Net\RandLANet.py", line 1121, in multi_scale_group
    gather_idx1 = tf.stack([batch_idx_tiled_k1, neigh_k1], axis=-1)
  File "C:\Users\Ayaan\anaconda3\envs\randlanet\lib\site-packages\tensorflow\python\ops\array_ops.py", line 874, in stack
    return gen_array_ops.pack(values, axis=axis, name=name)
  File "C:\Users\Ayaan\anaconda3\envs\randlanet\lib\site-packages\tensorflow\python\ops\gen_array_ops.py", line 5643, in pack
    "Pack", values=values, axis=axis, name=name)
  File "C:\Users\Ayaan\anaconda3\envs\randlanet\lib\site-packages\tensorflow\python\framework\op_def_library.py", line 787, in _apply_op_helper
    op_def=op_def)
  File "C:\Users\Ayaan\anaconda3\envs\randlanet\lib\site-packages\tensorflow\python\util\deprecation.py", line 488, in new_func
    return func(*args, **kwargs)
  File "C:\Users\Ayaan\anaconda3\envs\randlanet\lib\site-packages\tensorflow\python\framework\ops.py", line 3272, in create_op
    op_def=op_def)
  File "C:\Users\Ayaan\anaconda3\envs\randlanet\lib\site-packages\tensorflow\python\framework\ops.py", line 1768, in __init__
    self._traceback = tf_stack.extract_stack()

InvalidArgumentError (see above for traceback): Shapes of all inputs must match: values[0].shape = [4,16384,16] != values[1].shape = [4,65536,16]
	 [[{{node inference/Dec_LTA_3/stack}} = Pack[N=2, T=DT_INT32, axis=-1, _device="/job:localhost/replica:0/task:0/device:CPU:0"](inference/Dec_LTA_3/Tile_1, inference/clip_by_value)]]

Saved crash snapshot to: results\Sem3D_Run_20250611_085155\crash_snapshot
Training finished
****EPOCH 0****
Numerical error at step 1
Error details: Input to reshape is a tensor with 65536 values, but the requested shape has 262144
	 [[{{node inference/Reshape_33}} = Reshape[T=DT_INT32, Tshape=DT_INT32, _device="/job:localhost/replica:0/task:0/device:CPU:0"](inference/transpose_6, inference/Reshape_33/shape)]]

Caused by op 'inference/Reshape_33', defined at:
  File "main_Semantic3D.py", line 742, in <module>
    model = Network(dataset, cfg)
  File "D:\RandLA-Net\RandLANet.py", line 1371, in __init__
    self.logits = self.inference(self.inputs, self.is_training)
  File "D:\RandLA-Net\RandLANet.py", line 1463, in inference
    neigh_idx_k1 = knn_blocked(xyz_i, k1, block_size=4096)
  File "D:\RandLA-Net\RandLANet.py", line 1092, in knn_blocked
    result_padded = tf.reshape(idx_blocks_transposed, [B, num_blocks * block_size, k])
  File "C:\Users\Ayaan\anaconda3\envs\randlanet\lib\site-packages\tensorflow\python\ops\gen_array_ops.py", line 7546, in reshape
    "Reshape", tensor=tensor, shape=shape, name=name)
  File "C:\Users\Ayaan\anaconda3\envs\randlanet\lib\site-packages\tensorflow\python\framework\op_def_library.py", line 787, in _apply_op_helper
    op_def=op_def)
  File "C:\Users\Ayaan\anaconda3\envs\randlanet\lib\site-packages\tensorflow\python\util\deprecation.py", line 488, in new_func
    return func(*args, **kwargs)
  File "C:\Users\Ayaan\anaconda3\envs\randlanet\lib\site-packages\tensorflow\python\framework\ops.py", line 3272, in create_op
    op_def=op_def)
  File "C:\Users\Ayaan\anaconda3\envs\randlanet\lib\site-packages\tensorflow\python\framework\ops.py", line 1768, in __init__
    self._traceback = tf_stack.extract_stack()

InvalidArgumentError (see above for traceback): Input to reshape is a tensor with 65536 values, but the requested shape has 262144
	 [[{{node inference/Reshape_33}} = Reshape[T=DT_INT32, Tshape=DT_INT32, _device="/job:localhost/replica:0/task:0/device:CPU:0"](inference/transpose_6, inference/Reshape_33/shape)]]

Saved crash snapshot to: results\Sem3D_Run_20250611_093526\crash_snapshot
Training finished
****EPOCH 0****
Step 00000020  L_out=29.979  Acc=0.26  --- 1030007.77 ms/batch
****EPOCH 0****
****EPOCH 0****
Numerical error at step 1
Error details: Incompatible shapes: [4,4096,1] vs. [1,4,256]
	 [[{{node inference/map_1/while/while/add_1}} = Add[T=DT_FLOAT, _device="/job:localhost/replica:0/task:0/device:CPU:0"](inference/map_1/while/while/strided_slice_1, inference/map_1/while/while/strided_slice_3)]]

Caused by op 'inference/map_1/while/while/add_1', defined at:
  File "main_Semantic3D.py", line 742, in <module>
    model = Network(dataset, cfg)
  File "D:\RandLA-Net\RandLANet.py", line 1411, in __init__
    self.logits = self.inference(self.inputs, self.is_training)
  File "D:\RandLA-Net\RandLANet.py", line 1504, in inference
    neigh_idx_k2 = knn_blocked(xyz_i, k2, block_size=4096)
  File "D:\RandLA-Net\RandLANet.py", line 1134, in knn_blocked
    all_blocks = tf.map_fn(process_block, blocks, dtype=tf.int32)
  File "C:\Users\Ayaan\anaconda3\envs\randlanet\lib\site-packages\tensorflow\python\ops\functional_ops.py", line 460, in map_fn
    maximum_iterations=n)
  File "C:\Users\Ayaan\anaconda3\envs\randlanet\lib\site-packages\tensorflow\python\ops\control_flow_ops.py", line 3274, in while_loop
    return_same_structure)
  File "C:\Users\Ayaan\anaconda3\envs\randlanet\lib\site-packages\tensorflow\python\ops\control_flow_ops.py", line 2994, in BuildLoop
    pred, body, original_loop_vars, loop_vars, shape_invariants)
  File "C:\Users\Ayaan\anaconda3\envs\randlanet\lib\site-packages\tensorflow\python\ops\control_flow_ops.py", line 2929, in _BuildLoop
    body_result = body(*packed_vars_for_body)
  File "C:\Users\Ayaan\anaconda3\envs\randlanet\lib\site-packages\tensorflow\python\ops\control_flow_ops.py", line 3243, in <lambda>
    body = lambda i, lv: (i + 1, orig_body(*lv))
  File "C:\Users\Ayaan\anaconda3\envs\randlanet\lib\site-packages\tensorflow\python\ops\functional_ops.py", line 449, in compute
    packed_fn_values = fn(packed_values)
  File "D:\RandLA-Net\RandLANet.py", line 1125, in process_block
    tf.TensorShape([None, None, None])
  File "C:\Users\Ayaan\anaconda3\envs\randlanet\lib\site-packages\tensorflow\python\ops\control_flow_ops.py", line 3274, in while_loop
    return_same_structure)
  File "C:\Users\Ayaan\anaconda3\envs\randlanet\lib\site-packages\tensorflow\python\ops\control_flow_ops.py", line 2994, in BuildLoop
    pred, body, original_loop_vars, loop_vars, shape_invariants)
  File "C:\Users\Ayaan\anaconda3\envs\randlanet\lib\site-packages\tensorflow\python\ops\control_flow_ops.py", line 2929, in _BuildLoop
    body_result = body(*packed_vars_for_body)
  File "D:\RandLA-Net\RandLANet.py", line 1101, in body
    -2*tf.matmul(xi, xj, transpose_b=True))   # [B, b_i, c_j]
  File "C:\Users\Ayaan\anaconda3\envs\randlanet\lib\site-packages\tensorflow\python\ops\math_ops.py", line 862, in binary_op_wrapper
    return func(x, y, name=name)
  File "C:\Users\Ayaan\anaconda3\envs\randlanet\lib\site-packages\tensorflow\python\ops\gen_math_ops.py", line 310, in add
    "Add", x=x, y=y, name=name)
  File "C:\Users\Ayaan\anaconda3\envs\randlanet\lib\site-packages\tensorflow\python\framework\op_def_library.py", line 787, in _apply_op_helper
    op_def=op_def)
  File "C:\Users\Ayaan\anaconda3\envs\randlanet\lib\site-packages\tensorflow\python\util\deprecation.py", line 488, in new_func
    return func(*args, **kwargs)
  File "C:\Users\Ayaan\anaconda3\envs\randlanet\lib\site-packages\tensorflow\python\framework\ops.py", line 3272, in create_op
    op_def=op_def)
  File "C:\Users\Ayaan\anaconda3\envs\randlanet\lib\site-packages\tensorflow\python\framework\ops.py", line 1768, in __init__
    self._traceback = tf_stack.extract_stack()

InvalidArgumentError (see above for traceback): Incompatible shapes: [4,4096,1] vs. [1,4,256]
	 [[{{node inference/map_1/while/while/add_1}} = Add[T=DT_FLOAT, _device="/job:localhost/replica:0/task:0/device:CPU:0"](inference/map_1/while/while/strided_slice_1, inference/map_1/while/while/strided_slice_3)]]

Saved crash snapshot to: results\Sem3D_Run_20250612_063844\crash_snapshot
Training finished
****EPOCH 0****
Step 00000020  L_out=28.306  Acc=0.05  --- 1107809.79 ms/batch
****EPOCH 0****
****EPOCH 0****
****EPOCH 0****
Step 00000020  L_out=31.611  Acc=0.40  --- 79696.49 ms/batch
Step 00000040  L_out=34.237  Acc=0.36  --- 73120.72 ms/batch
Step 00000060  L_out=23.635  Acc=0.10  --- 73232.16 ms/batch
Step 00000080  L_out=20.753  Acc=0.11  --- 73006.47 ms/batch
Step 00000100  L_out=34.087  Acc=0.13  --- 73350.26 ms/batch
Step 00000120  L_out=8.723  Acc=0.42  --- 73024.06 ms/batch
Step 00000140  L_out=33.096  Acc=0.20  --- 73962.68 ms/batch
Step 00000160  L_out=21.957  Acc=0.38  --- 73478.50 ms/batch
Step 00000180  L_out=22.715  Acc=0.23  --- 71936.09 ms/batch
Step 00000200  L_out=28.191  Acc=0.17  --- 71576.32 ms/batch
Step 00000220  L_out=17.713  Acc=0.22  --- 75196.66 ms/batch
Step 00000240  L_out=33.655  Acc=0.32  --- 72380.83 ms/batch
Step 00000260  L_out=21.958  Acc=0.42  --- 72024.38 ms/batch
Step 00000280  L_out=12.728  Acc=0.13  --- 72136.23 ms/batch
Step 00000300  L_out=24.111  Acc=0.11  --- 76700.79 ms/batch
Step 00000320  L_out=21.137  Acc=0.13  --- 87054.65 ms/batch
Step 00000340  L_out=19.835  Acc=0.27  --- 78216.40 ms/batch
Step 00000360  L_out=24.892  Acc=0.06  --- 71332.96 ms/batch
Step 00000380  L_out=17.282  Acc=0.29  --- 71408.03 ms/batch
Step 00000400  L_out=14.746  Acc=0.17  --- 71830.57 ms/batch
****EPOCH 0****
****EPOCH 0****
****EPOCH 0****
****EPOCH 0****
Step 00000020  L_out=26.190  Acc=0.15  --- 685221.89 ms/batch
